File: data/Cable PVC 5C/Cable PVC 5C DATA_error_removed_data.csv
Time (min),Temperature (°C),Weight (mg),Heat Flow (mW),Temperature Difference (°C),Temperature Difference (µV),Sample Purge Flow (mL/min),Deriv. Weight (%/°C),Deriv. Heat Flow (W/(g·°C))
0.01266666,24.80184,8.615922,-4.506602,-0.2191676,-1.375399,100.0208,0.007798051,0.01005204
0.196,24.79516,8.614911,-4.546847,-0.224802,-1.410683,100.0027,0.007798481,0.01005263
0.3793334,24.85947,8.613695,-4.547318,-0.2248251,-1.411064,99.99972,0.00773438,0.009964012
0.5793332,25.09345,8.612975,-4.480103,-0.2152466,-1.352002,99.98031,0.00743835,0.009542919
0.7876668,25.55364,8.612406,-4.392256,-0.2026,-1.274688,99.98407,0.006894292,0.00882995
1.062667,26.52198,8.612118,-4.283414,-0.1866592,-1.178606,99.96202,0.005974584,0.00749439
1.304334,27.64122,8.611732,-4.21415,-0.1761559,-1.117076,100.0067,0.00514597,0.006204889
1.587666,29.19823,8.61148,-4.170319,-0.1688988,-1.077505,100.0385,0.004289504,0.00474021
1.821,30.58758,8.611163,-4.161346,-0.1666016,-1.068599,99.94425,0.001960649,0.00116367
2.137666,32.52038,8.61092,-4.175445,-0.1670447,-1.079501,100.039,0.001443953,-0.0011467
2.454333,34.3968,8.610741,-4.210761,-0.1703654,-1.109027,100.0132,0.001506358,-0.002076
2.746,36.01332,8.610559,-4.24971,-0.1743257,-1.141932,100.0316,0.001893663,-0.0022692
3.087666,37.7846,8.610379,-4.290598,-0.1783832,-1.176422,99.98082,0.002264184,-0.0019525
3.379333,39.20834,8.609891,-4.31509,-0.1805873,-1.196807,100.0096,0.002485324,-0.0014424
3.629333,40.38015,8.60957,-4.328011,-0.1814355,-1.207247,99.97411,0.002578708,-0.00094771
3.904334,41.64848,8.609374,-4.333188,-0.1811899,-1.210825,100.0383,0.00257012,-0.00044805
4.146,42.76168,8.609089,-4.334094,-0.1805013,-1.210776,99.97266,0.002391669,-7.9896e-05
4.412666,44.00734,8.608858,-4.329311,-0.1789889,-1.205648,99.98582,0.002158236,0.000189829
4.746,45.59602,8.608681,-4.320666,-0.1767425,-1.196871,100.0294,0.001948022,0.000310641
5.046,47.07583,8.608326,-4.31549,-0.1750494,-1.191224,100.0015,0.00175059,0.000237196
5.379334,48.75072,8.608181,-4.31195,-0.173442,-1.186856,100.0052,0.001602946,1.68653e-05
5.654332,50.15234,8.607978,-4.313977,-0.1727467,-1.187575,100.0196,0.001468606,-0.0002027
5.929332,51.5709,8.607804,-4.317717,-0.172267,-1.189785,100.0562,0.001477679,-0.0003975
6.204334,52.98918,8.607553,-4.325552,-0.1723062,-1.195582,100.0231,0.001513604,-0.00054223
6.529334,54.6562,8.607408,-4.335881,-0.1724942,-1.203379,100.0188,0.001573129,-0.00062251
6.879334,56.42442,8.607155,-4.34675,-0.1726725,-1.211562,99.99999,0.001607017,-0.00059664
7.187668,57.98216,8.606868,-4.35413,-0.1725783,-1.216856,100.0073,0.001698519,-0.0004995
7.521,59.64954,8.606732,-4.361447,-0.1724717,-1.222009,99.99794,0.001823606,-0.00036024
7.771,60.89224,8.606493,-4.364646,-0.1721148,-1.223874,100.0068,0.001889176,-0.00025133
8.012666,62.09293,8.606238,-4.366124,-0.171574,-1.224262,100.0089,0.001936356,-0.00015905
8.287666,63.46072,8.606024,-4.366519,-0.1708053,-1.223575,99.97149,0.001991884,-9.7816e-05
8.612668,65.08406,8.605762,-4.366692,-0.1698711,-1.222508,99.89016,0.001993456,-7.17e-05
8.887666,66.46553,8.605486,-4.365308,-0.1688928,-1.220252,99.99774,0.001883339,-6.8223e-05
9.229332,68.17168,8.605292,-4.369162,-0.1683634,-1.222338,100.0009,0.001660987,-8.9222e-05
9.479332,69.41788,8.60503,-4.37045,-0.1677982,-1.222527,100.005,0.00152603,-0.00011152
9.771,70.88439,8.604828,-4.37016,-0.1669206,-1.221163,100.0015,0.001278783,-0.00010455
10.10433,72.54859,8.604676,-4.372392,-0.1662395,-1.221863,100.0043,0.000866024,-5.2296e-05
10.41267,74.09708,8.604524,-4.374683,-0.1656398,-1.222704,100.0052,0.000327715,2.32417e-05
10.85433,76.3183,8.604629,-4.373004,-0.1642004,-1.219558,100.0363,-0.00036147,7.48158e-05
11.371,78.90154,8.604785,-4.366133,-0.1620186,-1.21158,99.99984,-0.00038823,-0.00013876
11.771,80.90343,8.604945,-4.37065,-0.1615368,-1.214027,100.0329,7.06333e-05,-0.0004808
12.20434,83.07616,8.604786,-4.386416,-0.1622789,-1.226203,100.0186,0.000640423,-0.0008196
12.53766,84.746,8.604707,-4.402817,-0.1633403,-1.239319,100.0137,0.000829514,-0.00092933
12.87934,86.45426,8.604522,-4.41757,-0.1641856,-1.250962,99.97059,0.000735253,-0.00090203
13.22934,88.20725,8.604382,-4.429863,-0.1647184,-1.260414,99.97937,0.000753817,-0.00080751
13.56266,89.86447,8.604338,-4.440639,-0.1651171,-1.268602,100.0055,0.000623103,-0.00071917
13.896,91.53699,8.604159,-4.45026,-0.1653788,-1.275774,100.0002,0.000506836,-0.00066756
14.27934,93.45519,8.604156,-4.460663,-0.165603,-1.283444,100.077,0.00041123,-0.00066307
14.646,95.30139,8.604022,-4.4695,-0.165687,-1.289799,99.99047,0.000220164,-0.000693
15.021,97.17876,8.604074,-4.481862,-0.1661487,-1.299218,99.9979,0.000196832,-0.00069527
15.37934,98.97394,8.604015,-4.494781,-0.1667565,-1.309185,100.0046,0.000233241,-0.00067388
15.80434,101.0874,8.604034,-4.505172,-0.1669504,-1.316696,100.0103,0.000393865,-0.00063226
16.10434,102.5866,8.603914,-4.512984,-0.1671358,-1.322411,99.98993,0.00047692,-0.00062741
16.46267,104.3814,8.603781,-4.521741,-0.167291,-1.328731,99.98003,0.000610814,-0.00065334
16.76266,105.8857,8.603678,-4.530638,-0.1675906,-1.335392,100.0203,0.000532935,-0.00068936
17.15434,107.8376,8.603665,-4.54287,-0.1680516,-1.344638,100.0175,0.00050729,-0.00073332
17.51266,109.6351,8.603618,-4.556024,-0.1686812,-1.354811,100.0266,0.000509387,-0.0007691
17.87934,111.4741,8.603549,-4.567171,-0.1690687,-1.363194,99.99155,0.000610252,-0.00078702
18.22934,113.2298,8.6034,-4.579734,-0.1696453,-1.372883,100.0034,0.000902064,-0.00078188
18.58767,115.013,8.603262,-4.592535,-0.1702277,-1.382754,99.98254,0.001309946,-0.00078767
18.946,116.8131,8.603012,-4.602578,-0.1705024,-1.390196,99.99376,0.001498092,-0.00079398
19.23767,118.2669,8.602705,-4.61231,-0.1709155,-1.397628,100.017,0.001715395,-0.00081799
19.596,120.0639,8.602572,-4.625873,-0.1716213,-1.408163,100.0079,0.00181273,-0.00086161
19.846,121.3143,8.602306,-4.636228,-0.1722058,-1.416296,100.0112,0.00171967,-0.00089564
20.16266,122.8964,8.602026,-4.64863,-0.1728663,-1.42597,100.0065,0.001327371,-0.00092925
20.43766,124.2664,8.601847,-4.65856,-0.173349,-1.433638,99.99399,0.001065656,-0.00095751
20.771,125.9346,8.601709,-4.672989,-0.1741811,-1.445024,100.0394,0.001009219,-0.00099111
21.196,128.0586,8.601824,-4.69168,-0.1752672,-1.459804,100.0049,0.001687598,-0.0010446
21.52934,129.7184,8.601636,-4.706776,-0.1761601,-1.471779,99.96632,0.002502294,-0.0010884
21.746,130.8122,8.601031,-4.718586,-0.1769424,-1.481307,99.98254,0.002917478,-0.0011135
21.95434,131.8603,8.600616,-4.726535,-0.1773361,-1.487483,99.97697,0.00329228,-0.0011368
22.21267,133.1422,8.600268,-4.74082,-0.1782899,-1.499034,100.0004,0.003325628,-0.0011514
22.46267,134.3904,8.599954,-4.75306,-0.1790432,-1.508822,99.98689,0.002945155,-0.001167
22.721,135.6811,8.599732,-4.767539,-0.1800045,-1.520535,99.95916,0.002407728,-0.0011725
22.93766,136.7652,8.599379,-4.776931,-0.1805254,-1.527953,100.0027,0.002191831,-0.0011749
23.246,138.3024,8.599238,-4.793466,-0.181607,-1.541282,99.96259,0.002072762,-0.0011772
23.50434,139.5964,8.599078,-4.805452,-0.182338,-1.550812,100.005,0.002027434,-0.0011774
23.81266,141.139,8.598858,-4.821724,-0.1834075,-1.56391,100.0002,0.00200934,-0.001199
24.03766,142.2563,8.598474,-4.833947,-0.1842227,-1.573777,99.99074,0.002081379,-0.0012204
24.371,143.9254,8.598306,-4.849543,-0.1851656,-1.58619,100.0049,0.00230169,-0.0012577
24.61267,145.1357,8.597961,-4.86293,-0.1860566,-1.59701,100.003,0.002628174,-0.0012896
24.946,146.8045,8.597764,-4.883291,-0.1874734,-1.613595,100.0129,0.00325456,-0.0013321
25.20434,148.0988,8.597424,-4.898336,-0.1884915,-1.625806,99.98976,0.003897089,-0.0013566
25.42934,149.2232,8.596934,-4.911262,-0.1893576,-1.636286,99.97028,0.004517162,-0.0013605
25.621,150.1798,8.596376,-4.923718,-0.1902412,-1.646484,100.0197,0.005061648,-0.0013568
25.83767,151.2563,8.5959,-4.935657,-0.1910179,-1.656131,100.0168,0.00558664,-0.0013587
26.046,152.3026,8.595468,-4.947646,-0.1918129,-1.665851,100.0105,0.005960531,-0.0013635
26.23767,153.2537,8.594946,-4.95922,-0.192599,-1.675276,99.98676,0.006190863,-0.0013714
26.43766,154.2575,8.594305,-4.970813,-0.1933661,-1.684682,100.0032,0.00663481,-0.0013808
26.65434,155.3364,8.593772,-4.982722,-0.1941288,-1.694301,100.0187,0.007091186,-0.0013943
26.83767,156.2547,8.593202,-4.994229,-0.1949165,-1.703697,99.98082,0.007398114,-0.0014031
27.02934,157.2126,8.592594,-5.006836,-0.1957939,-1.714022,99.98999,0.007672968,-0.001426
27.23767,158.2504,8.592019,-5.018666,-0.196575,-1.723606,99.98251,0.007988305,-0.0014533
27.421,159.1656,8.591001,-5.029954,-0.1973584,-1.732812,99.95772,0.00841366,-0.001478
27.61267,160.1251,8.590406,-5.042014,-0.1981984,-1.742658,100.0066,0.008985168,-0.0015001
27.81266,161.1282,8.589839,-5.055012,-0.199114,-1.753295,100.003,0.009738358,-0.0015176
27.996,162.0394,8.589093,-5.067638,-0.2000219,-1.76367,100.0085,0.01044203,-0.0015381
28.17934,162.9598,8.588251,-5.08036,-0.2009368,-1.774129,100.0099,0.0113332,-0.00156
28.36267,163.8814,8.587266,-5.09316,-0.2018558,-1.784654,99.99994,0.01237887,-0.0015865
28.546,164.7956,8.586274,-5.105082,-0.2026867,-1.794411,100.0132,0.013596,-0.0016037
28.72934,165.7071,8.585089,-5.117235,-0.2035391,-1.804373,99.97003,0.01472394,-0.0016093
28.921,166.6651,8.583938,-5.131153,-0.2045474,-1.815851,100.0316,0.01588914,-0.00161
29.10434,167.5823,8.582602,-5.143472,-0.20541,-1.825955,100.0129,0.01701543,-0.0016112
29.28766,168.4895,8.581076,-5.157459,-0.206437,-1.837526,99.93719,0.01810018,-0.0016156
29.471,169.4076,8.579678,-5.169416,-0.2072606,-1.847318,100.0551,0.01916243,-0.0016145
29.65434,170.3225,8.578278,-5.182449,-0.2081872,-1.858049,99.98871,0.02023587,-0.001613
29.83767,171.2398,8.576551,-5.1949,-0.2090529,-1.868269,99.96992,0.02135051,-0.0016121
30.021,172.1541,8.574738,-5.206252,-0.2098108,-1.877531,100.0044,0.02244463,-0.001622
30.20434,173.0641,8.572999,-5.220296,-0.2108298,-1.889149,99.97976,0.02360606,-0.001633
30.38767,173.9901,8.571136,-5.232828,-0.2116966,-1.89944,99.98803,0.02491777,-0.0016476
30.571,174.9044,8.569094,-5.245505,-0.2125753,-1.909859,100.0041,0.02619013,-0.0016655
30.75434,175.8224,8.566951,-5.259,-0.213531,-1.920994,99.98162,0.02744272,-0.0016858
30.93766,176.7381,8.564766,-5.273002,-0.2145342,-1.932573,99.99499,0.0288284,-0.0017049
31.121,177.6534,8.562434,-5.287121,-0.215549,-1.944259,100.0163,0.0302774,-0.001726
31.30434,178.5712,8.559953,-5.299786,-0.2164416,-1.95467,99.99991,0.03170312,-0.0017486
31.48767,179.4879,8.557436,-5.313566,-0.2174398,-1.966056,100.0487,0.0330769,-0.0017637
31.671,180.4011,8.554824,-5.32811,-0.21851,-1.978112,99.98546,0.03451095,-0.0017798
31.85434,181.3175,8.551972,-5.341544,-0.2194696,-1.989193,100.0,0.03593482,-0.0017978
32.03766,182.2354,8.548996,-5.356241,-0.22055,-2.001384,100.002,0.03736206,-0.001813
32.221,183.1511,8.546142,-5.369788,-0.2215153,-2.012564,99.99993,0.03884158,-0.0018386
32.40434,184.0678,8.543041,-5.384614,-0.2226045,-2.024871,100.0184,0.04030312,-0.0018599
32.58766,184.9777,8.539786,-5.399804,-0.2237245,-2.037492,99.9978,0.04177182,-0.0018846
32.771,185.8948,8.53648,-5.414791,-0.2248226,-2.049939,99.98226,0.04331761,-0.0019157
32.95433,186.809,8.532954,-5.428876,-0.2258325,-2.061595,99.9882,0.0450202,-0.0019524
33.13766,187.7245,8.529347,-5.444896,-0.2270241,-2.074945,100.0329,0.0468621,-0.0020043
33.321,188.6358,8.525587,-5.46095,-0.2282168,-2.088326,99.98611,0.04881892,-0.0020656
33.50433,189.5547,8.521894,-5.477218,-0.2294264,-2.101894,100.036,0.05085156,-0.0021232
33.68767,190.4672,8.517718,-5.493484,-0.2306338,-2.115461,100.0452,0.05299732,-0.0021914
33.871,191.393,8.513432,-5.511349,-0.2319896,-2.130426,100.0283,0.0552155,-0.002255
34.05433,192.3067,8.509039,-5.52969,-0.2333873,-2.14581,100.0151,0.05758164,-0.0023147
34.23767,193.2134,8.50434,-5.548793,-0.234857,-2.161865,100.0097,0.06001234,-0.0023748
34.421,194.1304,8.499584,-5.567274,-0.2362636,-2.177375,100.022,0.06251674,-0.0024344
34.60433,195.0363,8.494601,-5.587813,-0.2378627,-2.194689,99.95094,0.06500541,-0.002488
34.78766,195.9551,8.489478,-5.605755,-0.2392111,-2.209725,100.0409,0.0676781,-0.0025418
34.971,196.8766,8.483888,-5.627675,-0.2409298,-2.228242,99.97942,0.0704284,-0.0025876
35.15433,197.7937,8.47832,-5.647563,-0.2424576,-2.244982,99.97392,0.07335654,-0.0026352
35.33766,198.7067,8.47245,-5.668707,-0.2441213,-2.262824,100.0219,0.0766781,-0.0026988
35.521,199.6189,8.466261,-5.69075,-0.2458646,-2.281453,99.98246,0.07997025,-0.0027502
35.70433,200.534,8.459988,-5.712224,-0.2474755,-2.298874,100.0086,0.0832226,-0.002797
35.88766,201.4529,8.453397,-5.734395,-0.2492582,-2.317936,100.0316,0.08661359,-0.002825
36.071,202.3695,8.446353,-5.755886,-0.2509826,-2.336477,100.0047,0.09003094,-0.0028427
36.25433,203.2806,8.438751,-5.781736,-0.2531245,-2.358953,100.0209,0.09349984,-0.0028525
36.43767,204.1964,8.431375,-5.803588,-0.2548939,-2.378001,99.99347,0.09697961,-0.002846
36.621,205.1232,8.423611,-5.826465,-0.2567598,-2.397991,100.0407,0.1006143,-0.0028224
36.80433,206.0366,8.415676,-5.847942,-0.2585054,-2.41689,100.0183,0.1041384,-0.0027824
36.98767,206.9519,8.407321,-5.86975,-0.2602856,-2.436141,100.0011,0.107752,-0.0027348
37.171,207.8599,8.398731,-5.892306,-0.2621424,-2.45613,100.0288,0.111375,-0.0026748
37.35433,208.7751,8.389931,-5.912942,-0.2638224,-2.474504,99.97258,0.1153971,-0.00262
37.53766,209.693,8.3806,-5.933759,-0.2655234,-2.493121,100.0004,0.1194084,-0.0025665
37.721,210.6055,8.371072,-5.952473,-0.267038,-2.510023,100.0074,0.1234477,-0.0025194
37.90433,211.5192,8.361076,-5.973176,-0.2687396,-2.528704,100.0166,0.1274615,-0.002476
38.08766,212.4322,8.350966,-5.992057,-0.2702775,-2.54587,100.0247,0.1315401,-0.002446
38.271,213.3497,8.340419,-6.010344,-0.2717651,-2.562608,100.0075,0.1357356,-0.0024305
38.45433,214.2658,8.329546,-6.028292,-0.2732276,-2.579143,100.1505,0.1399918,-0.0024246
38.63766,215.1791,8.31842,-6.04736,-0.2747983,-2.59672,99.98592,0.1443216,-0.0024196
38.821,216.0942,8.306886,-6.065754,-0.2763113,-2.613788,99.94942,0.1486228,-0.0024102
39.00433,217.0158,8.294953,-6.086829,-0.2780702,-2.63321,100.0224,0.1531601,-0.0024132
39.18767,217.9202,8.282746,-6.10548,-0.2796262,-2.650667,100.0462,0.1574658,-0.0024049
39.371,218.837,8.270161,-6.125218,-0.2812962,-2.669101,100.0184,0.162167,-0.00239
39.55433,219.7525,8.257194,-6.14289,-0.2827836,-2.685832,99.99516,0.166869,-0.0023774
39.73767,220.6732,8.243926,-6.16169,-0.2843748,-2.703576,100.0286,0.1716538,-0.0023641
39.921,221.5876,8.230194,-6.181144,-0.2860334,-2.721998,100.0188,0.1765205,-0.0023468
40.10433,222.5076,8.216089,-6.198412,-0.2874948,-2.738564,100.0174,0.1815682,-0.0023389
40.28766,223.4227,8.201629,-6.216521,-0.2890396,-2.75596,99.98259,0.1867438,-0.0023322
40.471,224.3358,8.186634,-6.234829,-0.2906054,-2.773572,100.0048,0.1919702,-0.0023289
40.65433,225.2471,8.171387,-6.254428,-0.292293,-2.792386,99.97241,0.1973619,-0.0023165
40.83766,226.1694,8.155644,-6.271448,-0.2937452,-2.808966,100.0064,0.2028661,-0.0022961
41.021,227.0761,8.139365,-6.290594,-0.2954004,-2.827522,100.0037,0.2086224,-0.002277
41.20434,227.9923,8.122772,-6.310115,-0.2970868,-2.846404,100.0089,0.2146158,-0.0022479
41.38766,228.906,8.105844,-6.327068,-0.298549,-2.863172,99.95453,0.2210655,-0.0022128
41.571,229.8194,8.088269,-6.343621,-0.2999804,-2.879678,99.99249,0.2280684,-0.0021857
41.75434,230.7339,8.070306,-6.36088,-0.3014748,-2.896796,100.017,0.2354485,-0.0021711
41.93766,231.6457,8.051515,-6.37787,-0.3029525,-2.913799,99.969,0.2432457,-0.0021646
42.121,232.5715,8.032142,-6.393738,-0.304328,-2.929852,100.0046,0.2522662,-0.0021746
42.30434,233.4801,8.011957,-6.409738,-0.3057252,-2.946125,100.0202,0.2617299,-0.0021972
42.48766,234.3979,7.990937,-6.427234,-0.3072548,-2.963711,100.0329,0.2716316,-0.0022198
42.671,235.3132,7.969434,-6.44564,-0.3088684,-2.982138,99.98306,0.2817119,-0.0022423
42.85434,236.2337,7.946766,-6.464003,-0.3104778,-3.000553,100.004,0.2915416,-0.0022453
43.03766,237.142,7.923261,-6.482162,-0.3120764,-3.018884,100.015,0.3008572,-0.0022688
43.221,238.057,7.898911,-6.500744,-0.313719,-3.037554,99.98172,0.3098965,-0.0022973
43.40434,238.9692,7.873776,-6.517402,-0.315214,-3.054724,99.98969,0.3187671,-0.0023258
43.58766,239.8771,7.848194,-6.536048,-0.3168805,-3.073549,100.0114,0.3274549,-0.002352
43.771,240.7931,7.82231,-6.550481,-0.3181849,-3.088922,100.0134,0.3358389,-0.0023902
43.95434,241.7137,7.796153,-6.573676,-0.3202515,-3.111724,100.0055,0.3442813,-0.0024474
44.13766,242.6354,7.768396,-6.592618,-0.3219512,-3.131004,100.0088,0.3532374,-0.0025221
44.321,243.5448,7.740256,-6.613434,-0.323815,-3.15188,100.0205,0.3628406,-0.002618
44.50434,244.46,7.711411,-6.632915,-0.3255625,-3.17166,99.96738,0.3733568,-0.0027262
44.68766,245.3766,7.681843,-6.653381,-0.3273971,-3.192329,100.0102,0.3847534,-0.0028445
44.871,246.2925,7.651089,-6.677072,-0.3295117,-3.215767,99.97338,0.3966074,-0.0029479
45.05434,247.208,7.619394,-6.699708,-0.3315334,-3.238322,99.95469,0.4087967,-0.0030619
45.23766,248.1269,7.586772,-6.725105,-0.333791,-3.263226,100.0046,0.4214481,-0.0031732
45.421,249.035,7.55312,-6.750947,-0.3360891,-3.288548,100.0137,0.434361,-0.0032734
45.60434,249.947,7.518472,-6.777634,-0.3384556,-3.314579,99.99638,0.4473106,-0.0033401
45.78766,250.8648,7.482686,-6.806665,-0.3410222,-3.342633,99.9816,0.4600483,-0.0033805
45.971,251.7748,7.445761,-6.832984,-0.343354,-3.368406,100.0071,0.4722442,-0.0033883
46.15434,252.692,7.407903,-6.860484,-0.3457828,-3.395178,100.0062,0.4837516,-0.0033588
46.33766,253.6016,7.36925,-6.888,-0.3482146,-3.422019,100.0122,0.4943037,-0.0033081
46.521,254.5157,7.329656,-6.912576,-0.3503912,-3.44639,99.97212,0.5042243,-0.0032386
46.70434,255.4303,7.289228,-6.940015,-0.3528076,-3.473154,99.95497,0.5134287,-0.0031623
46.88766,256.347,7.248212,-6.964057,-0.3549387,-3.497175,100.0352,0.5221532,-0.003094
47.071,257.2695,7.206646,-6.986184,-0.3569015,-3.519563,100.0183,0.5308448,-0.0030275
47.25434,258.1801,7.16468,-7.01064,-0.3590792,-3.543972,100.0077,0.5396386,-0.002973
47.43766,259.095,7.122097,-7.032672,-0.3610558,-3.566328,100.0023,0.548894,-0.0029409
47.621,260.007,7.078781,-7.056137,-0.3631531,-3.589908,99.99576,0.5593908,-0.0029477
47.80434,260.9214,7.034686,-7.07886,-0.3651845,-3.612866,99.98853,0.5717729,-0.0030013
47.98766,261.8274,6.98964,-7.100235,-0.3671039,-3.634734,100.033,0.5863987,-0.0031001
48.171,262.7405,6.943686,-7.122851,-0.3691275,-3.657689,100.0116,0.6034224,-0.003222
48.35434,263.6608,6.896335,-7.147715,-0.3713344,-3.682505,100.0153,0.6231148,-0.0033642
48.53766,264.5725,6.8471,-7.175106,-0.3737512,-3.709424,99.98832,0.6457674,-0.0034921
48.721,265.4865,6.79605,-7.203695,-0.3762628,-3.737323,99.99172,0.6715976,-0.0035697
48.90434,266.4019,6.742685,-7.235956,-0.3790732,-3.768228,100.0002,0.7009936,-0.0035841
49.08766,267.3222,6.68681,-7.268115,-0.3818698,-3.799048,100.0015,0.734306,-0.0035112
49.271,268.2319,6.628272,-7.298726,-0.3845406,-3.828662,100.0001,0.7714436,-0.0033666
49.45434,269.1475,6.567139,-7.32732,-0.3870346,-3.85655,100.0076,0.8124722,-0.0032079
49.63766,270.0591,6.502698,-7.349597,-0.3890058,-3.879256,99.96631,0.8573926,-0.0031036
49.821,270.9722,6.434464,-7.370987,-0.3909026,-3.901258,99.99392,0.9046312,-0.0030714
50.00434,271.8884,6.362005,-7.386976,-0.3923534,-3.91884,100.0102,0.9517574,-0.0030771
50.18766,272.8066,6.28456,-7.404639,-0.3939413,-3.937824,99.98886,0.9951031,-0.0030337
50.371,273.7248,6.202424,-7.429316,-0.3961032,-3.962582,99.99759,1.031868,-0.002879
50.55434,274.638,6.116079,-7.462502,-0.398951,-3.994208,100.0107,1.06032,-0.0026333
50.73766,275.5472,6.02741,-7.497934,-0.4019795,-4.027694,100.0021,1.079409,-0.0023578
50.921,276.4623,5.93813,-7.524521,-0.4042781,-4.053905,99.97012,1.088502,-0.0021161
51.10434,277.377,5.850255,-7.536206,-0.4053684,-4.068048,100.0324,1.087941,-0.0019233
51.28766,278.2938,5.764295,-7.532778,-0.4052507,-4.069912,100.0238,1.078768,-0.0017815
51.471,279.2094,5.679668,-7.527498,-0.4049925,-4.070288,100.005,1.062532,-0.0017042
51.65434,280.1236,5.596348,-7.534449,-0.4057244,-4.080605,99.99976,1.041508,-0.001728
51.83766,281.0387,5.514473,-7.553772,-0.407457,-4.101018,99.98153,1.016477,-0.0018577
52.021,281.9495,5.434474,-7.578665,-0.4096382,-4.125972,99.99476,0.9873126,-0.0020194
52.20434,282.8594,5.35646,-7.606353,-0.4120382,-4.153156,100.017,0.9542151,-0.0021022
52.38766,283.779,5.280776,-7.628331,-0.4139724,-4.175689,99.97956,0.9147719,-0.0019648
52.571,284.693,5.208538,-7.646902,-0.4156348,-4.195508,100.0,0.8703306,-0.0015647
52.75434,285.6088,5.140518,-7.661962,-0.4170126,-4.212475,100.0084,0.8219078,-0.0009562
52.93768,286.5274,5.077432,-7.666809,-0.4175725,-4.221194,99.99299,0.7707597,-0.00023272
53.121,287.4434,5.018881,-7.664956,-0.4176038,-4.22458,100.0076,0.7185452,0.000518203
53.30434,288.36,4.964984,-7.655522,-0.4170352,-4.221893,100.0218,0.666867,0.001248805
53.48766,289.279,4.915325,-7.640538,-0.4160299,-4.214774,99.99368,0.615961,0.001940714
53.671,290.2008,4.86945,-7.618803,-0.4144963,-4.202289,100.0105,0.5694751,0.002524819
53.85434,291.1182,4.827214,-7.594534,-0.412771,-4.187828,99.97491,0.5267675,0.00298825
54.03766,292.033,4.787983,-7.567489,-0.4108404,-4.171266,100.0361,0.4877888,0.003332135
54.221,292.9524,4.751583,-7.536038,-0.4085672,-4.151188,100.0252,0.4524235,0.00355862
54.40434,293.8725,4.717702,-7.505219,-0.406357,-4.131726,99.98334,0.4201404,0.003683558
54.58766,294.7935,4.686209,-7.47329,-0.4040688,-4.111436,99.99219,0.3906087,0.003719536
54.771,295.7116,4.65684,-7.441969,-0.401843,-4.091754,100.007,0.363467,0.003688878
54.95434,296.63,4.629554,-7.413556,-0.399852,-4.074425,100.0006,0.3388703,0.003597792
55.13766,297.5472,4.604102,-7.384634,-0.3978298,-4.056733,100.0064,0.3161426,0.003452064
55.321,298.4648,4.580539,-7.35689,-0.3959247,-4.040042,99.91022,0.2948864,0.003278995
55.50434,299.3799,4.558275,-7.331562,-0.3942233,-4.025394,99.99986,0.2750101,0.00308167
55.68768,300.3002,4.537734,-7.306647,-0.39256,-4.011114,100.0153,0.2564201,0.002878867
55.871,301.219,4.517509,-7.285702,-0.3912104,-4.00001,100.042,0.238883,0.002651622
56.05434,302.137,4.499635,-7.266013,-0.3899656,-3.989959,99.97179,0.222299,0.002412018
56.23766,303.0548,4.483287,-7.24712,-0.3887913,-3.980621,99.9991,0.2065973,0.002167189
56.421,303.9709,4.467654,-7.231294,-0.3878598,-3.973752,100.0316,0.1917051,0.001913384
56.60434,304.8894,4.453209,-7.215697,-0.3869461,-3.967042,100.0266,0.1776211,0.001655678
56.78766,305.8052,4.440007,-7.204778,-0.3864006,-3.964102,99.95988,0.1641896,0.001386224
56.971,306.7258,4.427672,-7.195102,-0.385954,-3.96218,100.0088,0.1518315,0.001110165
57.15434,307.6442,4.416378,-7.186105,-0.3855609,-3.960792,100.0017,0.1405219,0.000849788
57.33766,308.563,4.405838,-7.181296,-0.3854895,-3.962704,100.0136,0.1298634,0.000588085
57.521,309.4758,4.396082,-7.176337,-0.3854137,-3.964572,99.99703,0.119978,0.000331373
57.70434,310.3946,4.38713,-7.177048,-0.3857656,-3.970838,99.98886,0.1108148,8.71635e-05
57.88766,311.3058,4.378847,-7.177718,-0.3861168,-3.977094,99.97651,0.1025544,-0.00015633
58.071,312.2221,4.371272,-7.177963,-0.3864359,-3.983033,100.0284,0.09470111,-0.00039533
58.25434,313.139,4.364189,-7.182605,-0.3870862,-3.99239,100.0006,0.08742394,-0.00062151
58.43768,314.054,4.357746,-7.188325,-0.3878182,-4.0026,100.0181,0.08080999,-0.00083813
58.621,314.9698,4.351768,-7.196441,-0.3887272,-4.014645,99.96008,0.07476406,-0.0010478
58.80434,315.8847,4.346222,-7.206282,-0.3897644,-4.028026,100.0057,0.069172,-0.0012582
58.98766,316.7985,4.341088,-7.216545,-0.390829,-4.0417,99.99862,0.06418952,-0.0014556
59.171,317.7056,4.336318,-7.229461,-0.392093,-4.057424,100.0149,0.05976435,-0.0016342
59.35434,318.623,4.331791,-7.242536,-0.3933796,-4.073252,100.0098,0.05569092,-0.0018169
59.53766,319.546,4.32768,-7.258255,-0.3948611,-4.091123,99.99672,0.05212257,-0.0019603
59.721,320.4682,4.323922,-7.275512,-0.3964516,-4.11014,99.9968,0.04884164,-0.0020753
59.90434,321.3814,4.320185,-7.292045,-0.3979848,-4.128572,99.97742,0.04597142,-0.00217
60.08766,322.2949,4.316766,-7.311939,-0.3997641,-4.149584,99.98953,0.04330899,-0.0022395
60.271,323.2057,4.313413,-7.33254,-0.401585,-4.171031,100.0032,0.04103428,-0.0022822
60.45434,324.1163,4.310293,-7.348095,-0.4030278,-4.188578,100.0133,0.03894346,-0.0023064
60.63766,325.0344,4.307428,-7.365997,-0.4046368,-4.207882,99.99951,0.03704708,-0.0023098
60.821,325.9533,4.304504,-7.385674,-0.4063675,-4.228466,100.0161,0.03516257,-0.0022984
61.00434,326.8639,4.301812,-7.402876,-0.4079195,-4.247223,99.96764,0.03338757,-0.0022693
61.18768,327.7844,4.299267,-7.420416,-0.4094784,-4.266059,100.0174,0.03175088,-0.0022449
61.371,328.6934,4.296909,-7.439766,-0.411171,-4.286304,100.0323,0.03022857,-0.0022243
61.55434,329.6067,4.294557,-7.456276,-0.4126461,-4.304306,99.99889,0.02882965,-0.0021898
61.73766,330.522,4.292472,-7.47425,-0.4142208,-4.323364,99.99392,0.02745611,-0.0021461
61.921,331.4334,4.290404,-7.490608,-0.415675,-4.34119,99.99447,0.02616688,-0.0021113
62.10434,332.3468,4.288388,-7.507439,-0.417154,-4.359289,99.98928,0.02498403,-0.0020874
62.28766,333.2606,4.286485,-7.52271,-0.4185112,-4.376128,100.0138,0.02387258,-0.0020817
62.471,334.1748,4.284627,-7.538113,-0.419876,-4.393074,99.99838,0.02281778,-0.0021054
62.65434,335.0996,4.28279,-7.552884,-0.4211848,-4.409468,100.0014,0.02186766,-0.0021462
62.83766,336.0134,4.281248,-7.570454,-0.4226956,-4.427985,99.97824,0.02098496,-0.002207
63.021,336.9355,4.279532,-7.58789,-0.424185,-4.446303,100.0116,0.02009538,-0.0022706
63.20434,337.847,4.278055,-7.606658,-0.4257695,-4.465591,99.97528,0.0192462,-0.0023427
63.38766,338.7608,4.276593,-7.626434,-0.427429,-4.485578,99.97176,0.01842234,-0.0024066
63.571,339.6734,4.275138,-7.645938,-0.429061,-4.505294,99.99774,0.01771054,-0.0024586
63.75434,340.5898,4.273676,-7.66683,-0.430782,-4.525964,100.0241,0.01704434,-0.0024923
63.93768,341.4998,4.272421,-7.685171,-0.4323119,-4.544634,99.98262,0.01632098,-0.0025189
64.121,342.4202,4.271256,-7.705928,-0.4340056,-4.565064,99.98679,0.0156607,-0.00254
64.30434,343.332,4.270037,-7.725063,-0.4355799,-4.584254,99.98462,0.01506036,-0.0025553
64.48766,344.248,4.268836,-7.744872,-0.4371887,-4.603818,99.96085,0.01444184,-0.0025755
64.671,345.1587,4.267732,-7.765634,-0.4388606,-4.624068,99.98706,0.01394468,-0.0025973
64.85434,346.0789,4.26676,-7.786089,-0.4404985,-4.64399,100.0093,0.01354464,-0.002634
65.03766,346.9938,4.265636,-7.806834,-0.4421504,-4.664072,100.0167,0.01314849,-0.0026647
65.221,347.9042,4.264616,-7.827395,-0.4437842,-4.683988,99.98619,0.0127604,-0.0027007
65.40434,348.819,4.263732,-7.849889,-0.4455359,-4.705146,100.0556,0.01243923,-0.0027385
65.58768,349.7334,4.262636,-7.871142,-0.4471996,-4.725425,99.97388,0.01220834,-0.0027745
65.771,350.6494,4.261671,-7.894254,-0.4489809,-4.746958,100.0023,0.01198641,-0.0028178
65.95434,351.5619,4.26084,-7.915315,-0.4506078,-4.766869,100.0195,0.01182894,-0.0028644
66.13766,352.4765,4.259914,-7.938171,-0.4523528,-4.78806,100.0228,0.01166811,-0.0029172
66.32934,353.4309,4.258966,-7.961536,-0.4541313,-4.809752,100.0143,0.01150326,-0.0029722
66.51266,354.3468,4.25806,-7.984648,-0.455873,-4.830946,100.0334,0.01134324,-0.0030356
66.696,355.2629,4.25721,-8.010324,-0.457785,-4.853972,99.9935,0.01131405,-0.0031
66.87934,356.1792,4.256178,-8.034782,-0.4596018,-4.876012,99.97222,0.01132795,-0.0031718
67.06268,357.0926,4.255402,-8.059712,-0.461447,-4.898383,99.96476,0.01128977,-0.003232
67.246,358.013,4.254628,-8.085391,-0.4633324,-4.921132,100.0053,0.01136035,-0.0032809
67.42934,358.9221,4.253716,-8.112226,-0.4653035,-4.944715,99.97613,0.01149132,-0.0033265
67.61266,359.8326,4.252696,-8.139376,-0.4672862,-4.968446,100.0284,0.01157977,-0.0033583
67.796,360.7513,4.251836,-8.165681,-0.4691938,-4.991394,99.99749,0.01167404,-0.0033846
67.97934,361.67,4.251004,-8.19311,-0.4711738,-5.015152,99.99962,0.01190061,-0.0034024
68.16266,362.5829,4.249942,-8.219722,-0.4730903,-5.038252,99.98705,0.01209673,-0.0034069
68.346,363.4956,4.248932,-8.246322,-0.474993,-5.06121,99.99218,0.01221662,-0.0033961
68.52934,364.4113,4.248096,-8.272507,-0.4768606,-5.083836,100.0154,0.012307,-0.0033834
68.71268,365.3242,4.24709,-8.299862,-0.4787972,-5.107203,99.9878,0.01244441,-0.0033639
68.896,366.2387,4.246046,-8.328076,-0.4807829,-5.131118,100.0023,0.012575,-0.0033436
69.08768,367.197,4.244974,-8.355111,-0.482682,-5.154264,100.0184,0.01270738,-0.0033228
69.271,368.1094,4.244031,-8.379843,-0.4844159,-5.175542,100.0025,0.01279762,-0.003304
69.45434,369.0235,4.24299,-8.406457,-0.4862657,-5.198071,100.0212,0.01293506,-0.0032854
69.63766,369.9365,4.242066,-8.431774,-0.48802,-5.219598,99.98939,0.01301325,-0.003275
69.821,370.8501,4.240944,-8.456374,-0.4897202,-5.240578,99.96441,0.01310331,-0.0032705
70.00434,371.7689,4.239775,-8.482282,-0.4914964,-5.262392,100.0062,0.01323367,-0.0032821
70.18768,372.6782,4.238922,-8.509262,-0.493339,-5.284918,100.0249,0.01333959,-0.0032962
70.371,373.5976,4.237808,-8.533624,-0.4949968,-5.305512,99.99664,0.01350219,-0.0033022
70.55434,374.5162,4.236684,-8.560058,-0.4967858,-5.327526,99.99694,0.01366516,-0.003312
70.73766,375.4328,4.235627,-8.586931,-0.498596,-5.349784,100.0173,0.01382732,-0.0033158
70.921,376.3412,4.234556,-8.612901,-0.500342,-5.371363,99.99092,0.01407394,-0.0033173
71.10434,377.2566,4.233518,-8.640082,-0.5021558,-5.39369,99.97296,0.01439003,-0.0033105
71.28766,378.1708,4.232284,-8.666194,-0.5039015,-5.415234,99.97657,0.01467518,-0.0033032
71.471,379.0883,4.23119,-8.691789,-0.5056084,-5.436314,100.0074,0.01495143,-0.0032874
71.65434,380.0017,4.230028,-8.717249,-0.5073009,-5.457258,99.99571,0.01527975,-0.0032698
71.83768,380.913,4.228747,-8.744516,-0.5091075,-5.479442,100.0037,0.01558818,-0.0032458
72.021,381.8272,4.227576,-8.768725,-0.5107011,-5.499351,100.0101,0.0159304,-0.0032295
72.20434,382.7459,4.226224,-8.794754,-0.5124097,-5.520535,100.0408,0.01645796,-0.0032209
72.38766,383.66,4.224948,-8.82002,-0.5140596,-5.541084,100.0197,0.0171811,-0.0032108
72.571,384.571,4.223618,-8.84461,-0.5156606,-5.561124,100.0326,0.01780271,-0.0032081
72.75434,385.489,4.222321,-8.869025,-0.517243,-5.581,99.98912,0.01836853,-0.003218
72.93768,386.3993,4.220878,-8.894314,-0.5188784,-5.60145,100.0093,0.01886692,-0.003232
73.121,387.3191,4.219078,-8.920429,-0.5205567,-5.622388,100.0252,0.01940014,-0.0032545
73.30434,388.2367,4.217352,-8.945665,-0.5221726,-5.64267,99.96432,0.01993681,-0.0032854
73.48766,389.1527,4.215968,-8.971094,-0.5237978,-5.663079,99.99898,0.02041884,-0.0033292
73.671,390.065,4.21441,-8.998581,-0.5255493,-5.68485,100.03,0.02088593,-0.0033693
73.85434,390.9848,4.212869,-9.024231,-0.5271754,-5.705312,99.97681,0.02128328,-0.0033901
74.03766,391.8984,4.211122,-9.051501,-0.528899,-5.726819,100.0289,0.02171,-0.0033982
74.221,392.8161,4.209346,-9.078495,-0.5305982,-5.748096,99.99876,0.02229951,-0.0033929
74.40434,393.7247,4.20755,-9.107842,-0.5324492,-5.771025,100.0173,0.02311704,-0.0033742
74.58768,394.6384,4.205809,-9.135108,-0.5341526,-5.792362,99.99008,0.02394158,-0.0033527
74.771,395.5491,4.203896,-9.160519,-0.5357354,-5.812421,99.9903,0.02486506,-0.0033399
74.95434,396.468,4.201807,-9.18421,-0.5371976,-5.831199,99.99434,0.02577867,-0.0033158
75.13766,397.3842,4.199855,-9.209494,-0.5387598,-5.851079,99.984,0.0267581,-0.0032883
75.321,398.3006,4.197788,-9.235556,-0.5403739,-5.871443,99.99997,0.02787013,-0.0032667
75.50434,399.215,4.195502,-9.261616,-0.5419864,-5.891765,99.97344,0.02904325,-0.0032564
75.68768,400.1272,4.193206,-9.289544,-0.5437168,-5.913394,99.98431,0.0302628,-0.0032516
75.871,401.0417,4.190728,-9.315441,-0.5453075,-5.933507,99.96106,0.03157825,-0.0032567
76.05434,401.956,4.188274,-9.34004,-0.5468121,-5.952709,99.98929,0.03301953,-0.0032602
76.23766,402.8702,4.185574,-9.36539,-0.5483579,-5.972364,99.97545,0.03453076,-0.003259
76.421,403.787,4.182791,-9.39086,-0.5499058,-5.99207,99.98561,0.03603472,-0.0032494
76.60434,404.7017,4.179925,-9.415428,-0.5513928,-6.011124,100.0314,0.03760137,-0.0032417
76.78766,405.6168,4.176861,-9.44232,-0.5530224,-6.031756,99.98035,0.03931675,-0.0032432
76.971,406.5328,4.17377,-9.46884,-0.5546212,-6.052063,99.98105,0.04112988,-0.0032472
77.15434,407.4466,4.170419,-9.493599,-0.556104,-6.071122,99.97898,0.0429725,-0.00325
77.33768,408.3621,4.16707,-9.518989,-0.5576206,-6.090564,99.98621,0.04492644,-0.0032613
77.521,409.2812,4.163432,-9.54384,-0.5590962,-6.109582,100.0061,0.04701788,-0.0032655
77.70434,410.1978,4.159627,-9.570187,-0.5606605,-6.12958,100.0311,0.04912344,-0.0032679
77.88766,411.1134,4.155617,-9.595585,-0.562159,-6.148871,99.99868,0.0513872,-0.0032898
78.071,412.027,4.151547,-9.621861,-0.5637088,-6.168741,99.96447,0.05378153,-0.0033509
78.25434,412.9434,4.14729,-9.648728,-0.5652867,-6.188938,99.99516,0.05640379,-0.0034721
78.43768,413.853,4.142687,-9.67377,-0.5667456,-6.207824,100.015,0.0590921,-0.0036411
78.621,414.7664,4.138066,-9.700311,-0.5682912,-6.227694,99.96797,0.0619329,-0.0038328
78.80434,415.6833,4.133119,-9.728364,-0.5699219,-6.248506,99.97259,0.0649123,-0.004022
78.98766,416.5988,4.127995,-9.760314,-0.5717882,-6.271921,99.99509,0.06807926,-0.00419
79.171,417.507,4.122368,-9.799788,-0.5741189,-6.300451,100.0023,0.0713003,-0.0043297
79.35434,418.4221,4.116787,-9.838889,-0.5764199,-6.328618,100.0046,0.07466165,-0.0044477
79.53766,419.338,4.110693,-9.878069,-0.5787157,-6.35673,100.0413,0.07823196,-0.0045123
79.721,420.2539,4.10442,-9.912505,-0.5807114,-6.381584,100.0039,0.0818885,-0.0045514
79.90434,421.1681,4.097793,-9.946138,-0.5826462,-6.405769,99.98368,0.08564838,-0.0046096
80.08768,422.0822,4.091122,-9.980099,-0.5845936,-6.430114,100.0106,0.08979032,-0.0046922
80.271,422.9986,4.083869,-10.01547,-0.5866179,-6.455332,99.97743,0.09412551,-0.0048159
80.45434,423.9108,4.07635,-10.0479,-0.5884559,-6.47852,100.0126,0.0984841,-0.0049899
80.63766,424.8254,4.068421,-10.0864,-0.5906536,-6.50568,99.98886,0.1029341,-0.0052166
80.821,425.7406,4.060317,-10.13451,-0.5934309,-6.539253,100.0062,0.1074075,-0.005487
81.00434,426.651,4.051224,-10.18133,-0.5961195,-6.571872,100.023,0.111971,-0.0058228
81.18768,427.566,4.042354,-10.22652,-0.5986944,-6.603266,99.98725,0.1164804,-0.0061488
81.371,428.4776,4.033106,-10.27276,-0.601323,-6.635278,100.0198,0.1210359,-0.006408
81.55434,429.3944,4.023429,-10.32294,-0.6041773,-6.669811,99.93536,0.1256062,-0.0065576
81.73766,430.3076,4.013305,-10.37803,-0.6073196,-6.70755,100.0089,0.1301233,-0.0066048
81.921,431.2174,4.002992,-10.44245,-0.611016,-6.751437,99.99681,0.13448,-0.0065685
82.10434,432.1324,3.992276,-10.49812,-0.6141631,-6.789292,99.95938,0.1389987,-0.0064601
82.28766,433.0449,3.981045,-10.54762,-0.6169264,-6.822944,100.002,0.1434226,-0.0062529
82.471,433.9616,3.969396,-10.59498,-0.6195443,-6.855011,100.0059,0.1477389,-0.0059371
82.65434,434.8752,3.957666,-10.64054,-0.6220421,-6.88577,100.012,0.1518004,-0.0055099
82.83768,435.7868,3.945456,-10.68085,-0.624214,-6.912951,100.0129,0.1555998,-0.0049413
83.021,436.7029,3.9331,-10.7214,-0.6263848,-6.94014,100.0082,0.1590666,-0.0042928
83.20434,437.613,3.920428,-10.75716,-0.6282602,-6.96406,99.98078,0.1622316,-0.0037237
83.38766,438.5266,3.907334,-10.78956,-0.6299309,-6.98562,99.97718,0.1650716,-0.0032904
83.571,439.439,3.894164,-10.8126,-0.6310332,-7.000891,100.0272,0.1675634,-0.0030037
83.75434,440.3534,3.880778,-10.82084,-0.6312414,-7.00626,100.001,0.169678,-0.0028944
83.93768,441.275,3.867295,-10.81812,-0.6307854,-7.004262,99.99997,0.1714298,-0.0029438
84.12101,442.191,3.85346,-10.83951,-0.6317657,-7.018216,100.0178,0.1727681,-0.0031486
84.30434,443.1044,3.839816,-10.87178,-0.6333859,-7.03928,100.0122,0.1736951,-0.0034961
84.48766,444.0224,3.825954,-10.90426,-0.6350041,-7.060343,100.0113,0.1744362,-0.0039621
84.671,444.9404,3.811986,-10.9434,-0.6370074,-7.085706,100.0259,0.1751344,-0.0044785
84.85434,445.8509,3.798222,-10.9836,-0.6390632,-7.11165,99.989,0.1761155,-0.0049477
85.03766,446.7679,3.78437,-11.02384,-0.641106,-7.137482,99.96108,0.1769168,-0.0053188
85.22101,447.6839,3.770622,-11.06501,-0.6431934,-7.163845,99.93199,0.1761869,-0.0056033
85.40434,448.5922,3.756818,-11.10782,-0.6453682,-7.191176,99.98859,0.1753126,-0.005822
85.58768,449.507,3.742662,-11.15263,-0.647644,-7.219672,100.0335,0.1743611,-0.0059864
85.77101,450.426,3.727894,-11.20517,-0.650357,-7.253064,99.99747,0.1734208,-0.006133
85.95434,451.3417,3.713628,-11.26362,-0.6534043,-7.290214,99.98064,0.1723957,-0.0062686
86.13766,452.2532,3.702379,-11.31469,-0.6560047,-7.322391,99.95928,0.1712569,-0.00637
86.321,453.1647,3.688808,-11.35954,-0.6582265,-7.350366,100.0108,0.1697931,-0.0064316
86.50434,454.078,3.67532,-11.40715,-0.6605942,-7.379991,99.99266,0.1680912,-0.0064452
86.68768,454.9915,3.661762,-11.45837,-0.663158,-7.411834,99.96832,0.16627,-0.0064026
86.87101,455.9052,3.648541,-11.51181,-0.6658357,-7.444976,100.0002,0.1649422,-0.0063581
87.05434,456.8214,3.63526,-11.56308,-0.668372,-7.476578,100.0198,0.1637298,-0.0063366
87.23766,457.732,3.622538,-11.61482,-0.6709238,-7.50835,99.96368,0.1609544,-0.0063075
87.421,458.6456,3.609877,-11.66467,-0.6733559,-7.538713,99.97968,0.1577228,-0.0062332
87.60434,459.5608,3.597702,-11.71094,-0.6755662,-7.566643,100.0283,0.1541562,-0.0061401
87.78766,460.4759,3.585522,-11.76052,-0.6779532,-7.596554,99.99964,0.150514,-0.006038
87.97101,461.393,3.573744,-11.80561,-0.6800641,-7.623402,100.0261,0.1467247,-0.0059448
88.15434,462.3062,3.562384,-11.85198,-0.682238,-7.650968,100.0073,0.1428694,-0.0058501
88.33768,463.2239,3.551174,-11.89739,-0.6843398,-7.67776,99.9825,0.1388955,-0.0057669
88.52101,464.1357,3.540498,-11.94409,-0.6865056,-7.705282,100.0099,0.134877,-0.0056896
88.70434,465.0431,3.529961,-11.98958,-0.6885901,-7.731894,100.0042,0.1306797,-0.0056137
88.88766,465.962,3.51983,-12.03296,-0.6905309,-7.756926,100.0032,0.1265315,-0.0055541
89.071,466.874,3.510076,-12.07496,-0.6923842,-7.780982,99.96649,0.1223816,-0.0054952
89.25434,467.787,3.500562,-12.11806,-0.6942864,-7.805621,100.0049,0.1181391,-0.0054476
89.43768,468.6996,3.49136,-12.15825,-0.696009,-7.828244,100.0263,0.1139028,-0.005422
89.62101,469.6144,3.482667,-12.20175,-0.6979059,-7.852866,100.0046,0.1096781,-0.0054265
89.80434,470.53,3.474174,-12.24396,-0.6997139,-7.876484,100.0021,0.1055075,-0.0054619
89.98766,471.4461,3.46595,-12.28584,-0.7014893,-7.899765,99.98236,0.1014081,-0.0055199
90.171,472.3653,3.458235,-12.3306,-0.7034125,-7.924735,99.98974,0.09741845,-0.0055805
90.35434,473.2779,3.450756,-12.37467,-0.7052876,-7.949176,100.0069,0.09347911,-0.0056511
90.53766,474.1942,3.443478,-12.41966,-0.7071968,-7.974005,99.98066,0.08963242,-0.0057088
90.72101,475.1072,3.436574,-12.46576,-0.7091578,-7.999441,100.0066,0.08587524,-0.0057537
90.90434,476.0182,3.43005,-12.5124,-0.7111358,-8.025092,100.016,0.08222968,-0.0057825
91.08768,476.9344,3.423648,-12.55744,-0.7130053,-8.049538,99.98541,0.07866572,-0.0057949
91.27101,477.85,3.41767,-12.60512,-0.7150102,-8.075518,99.99084,0.07528574,-0.0058018
91.45434,478.7619,3.411956,-12.64857,-0.716768,-8.098694,99.97231,0.07229119,-0.005813
91.63766,479.6742,3.406472,-12.69358,-0.718599,-8.122708,100.0233,0.06937582,-0.0058306
91.821,480.5912,3.40112,-12.7389,-0.720429,-8.146744,99.99851,0.06653606,-0.0058772
92.00434,481.5062,3.39624,-12.78514,-0.7222984,-8.171241,99.99325,0.06378186,-0.005974
92.18768,482.4219,3.39138,-12.83076,-0.7241178,-8.195191,99.99019,0.06109715,-0.0061162
92.37101,483.331,3.386075,-12.87823,-0.7260312,-8.220206,99.97256,0.05851152,-0.0063585
92.55434,484.2476,3.381828,-12.9279,-0.728046,-8.2464,100.0009,0.05591419,-0.0070383
92.73766,485.1628,3.37758,-12.97952,-0.730155,-8.27368,100.0331,0.05335526,-0.0077532
92.921,486.0739,3.37345,-13.03354,-0.7323851,-8.302343,99.95819,0.05091328,-0.008375
93.10434,486.993,3.369696,-13.09197,-0.734836,-8.333554,100.0336,0.04848484,-0.0088768
93.28766,487.9059,3.365906,-13.15501,-0.7375304,-8.367535,99.97785,0.0461911,-0.0092
93.47101,488.8234,3.362422,-13.29978,-0.7447099,-8.45245,100.0285,0.04430248,-0.0093413
93.65434,489.7394,3.359109,-13.37504,-0.7480331,-8.493644,99.99515,0.04247668,-0.0092931
93.83768,490.6478,3.355822,-13.4399,-0.7507718,-8.528205,100.0425,0.04075098,-0.0090483
94.02101,491.5572,3.352698,-13.50505,-0.7535076,-8.56278,99.99842,0.03921122,-0.0086148
94.20434,492.4664,3.349678,-13.56091,-0.7557178,-8.591387,100.0078,0.03768172,-0.0077027
94.38766,493.3792,3.346785,-13.61659,-0.7578979,-8.619679,99.98876,0.03627115,-0.00659
94.571,494.2952,3.343968,-13.67291,-0.7600944,-8.648189,99.99956,0.03497503,-0.0059352
94.75434,495.205,3.341398,-13.72708,-0.7621631,-8.675247,100.0417,0.03373181,-0.0055424
94.93768,496.1202,3.33866,-13.7796,-0.7641206,-8.701079,100.0151,0.0325383,-0.0053313
95.12101,497.0402,3.336264,-13.77044,-0.7627032,-8.6885,100.0105,0.03147295,-0.0053147
95.30434,497.9578,3.33391,-13.79559,-0.763147,-8.6971,99.99452,0.03045228,-0.005443
95.48766,498.8718,3.33139,-13.84494,-0.7648974,-8.720564,99.99879,0.02955077,-0.0057035
95.671,499.794,3.329202,-13.90075,-0.7669744,-8.747798,100.072,0.02874954,-0.0061161
95.85434,500.7087,3.327,-13.95922,-0.7691869,-8.77657,99.99761,0.02798211,-0.0066573
96.03766,501.6278,3.324742,-14.02186,-0.7716038,-8.807703,100.0082,0.02733295,-0.0075447
96.22101,502.5422,3.322695,-14.07671,-0.7735878,-8.833916,99.98874,0.02669712,-0.0081467
96.40434,503.4541,3.32064,-14.13868,-0.7759424,-8.864363,100.0082,0.02603277,-0.0084472
96.58768,504.3646,3.318474,-14.20243,-0.7783776,-8.895746,100.0326,0.0254402,-0.0086107
96.77101,505.2767,3.316585,-14.26641,-0.7808074,-8.927093,99.99374,0.02489612,-0.0086144
96.95434,506.1918,3.314624,-14.37882,-0.7858114,-8.987924,99.97831,0.02438658,-0.0085083
97.13766,507.1019,3.312781,-14.4469,-0.7884256,-9.021428,100.0354,0.02390631,-0.0083148
97.321,508.013,3.311014,-14.50425,-0.790448,-9.048194,99.95956,0.02340882,-0.0080172
97.50434,508.927,3.309148,-14.56051,-0.792394,-9.074101,100.0196,0.02295995,-0.0076876
97.68768,509.84,3.307309,-14.60847,-0.7938839,-9.094803,99.99503,0.02253073,-0.0073203
97.87101,510.7533,3.305561,-14.66155,-0.7956318,-9.118491,100.0031,0.02210205,-0.0069554
98.05434,511.6704,3.30381,-14.7152,-0.7973928,-9.142328,100.0079,0.02176706,-0.0068896
98.23766,512.5881,3.302142,-14.76563,-0.7989658,-9.164062,99.99984,0.02146156,-0.0069856
98.421,513.5156,3.300438,-14.82186,-0.8008228,-9.18908,99.97368,0.02111217,-0.0071407
98.60434,514.4324,3.298874,-14.87911,-0.8027314,-9.214676,99.99747,0.02078418,-0.0073378
98.78766,515.3485,3.297269,-14.93758,-0.804689,-9.240868,99.99803,0.02046844,-0.0075206
98.97101,516.2687,3.295554,-14.99987,-0.8068301,-9.269187,100.0085,0.02022133,-0.0076876
99.15434,517.19,3.29398,-15.06375,-0.8090394,-9.298303,100.0008,0.02003946,-0.0078303
99.33768,518.1046,3.2924,-15.12745,-0.8112338,-9.327226,99.97711,0.01985308,-0.0079245
99.52101,519.0241,3.290833,-15.19071,-0.8133882,-9.355681,100.0008,0.01966834,-0.0079864
99.70434,519.9388,3.289326,-15.25374,-0.815522,-9.383899,100.0294,0.01950053,-0.0080235
99.88766,520.8591,3.287744,-15.31775,-0.8176861,-9.412499,100.0208,0.01987556,-0.0080153
100.071,521.7793,3.286241,-15.38209,-0.819854,-9.441153,100.0001,0.0201797,-0.0079713
100.2543,522.693,3.28475,-15.44529,-0.8219532,-9.46904,100.0206,0.02036641,-0.0079063
100.4377,523.612,3.28329,-15.50717,-0.8239645,-9.495931,99.98395,0.02048039,-0.0078316
100.621,524.5282,3.281755,-15.57174,-0.826105,-9.524328,99.99775,0.02044365,-0.0077788
100.8043,525.4465,3.27928,-15.6313,-0.8279694,-9.549558,99.95754,0.02019459,-0.0077498
100.9877,526.3641,3.277887,-15.68986,-0.8297684,-9.574056,100.0095,0.01988234,-0.007752
101.171,527.2828,3.276443,-15.74628,-0.8314431,-9.597132,100.0203,0.01948968,-0.0077772
101.3543,528.2006,3.27495,-15.80669,-0.8333118,-9.622469,100.0424,0.01899538,-0.0078443
101.5377,529.118,3.273544,-15.87128,-0.8353826,-9.650165,100.0392,0.01844306,-0.0079498
101.721,530.0362,3.272286,-15.93496,-0.8373938,-9.677186,99.98546,0.01789384,-0.0080958
101.9043,530.9546,3.270763,-16.00137,-0.8395324,-9.705688,99.98518,0.01789995,-0.0082412
102.0877,531.8787,3.269422,-16.0656,-0.8415399,-9.732701,99.98086,0.0179366,-0.0083576
102.271,532.793,3.26802,-16.13241,-0.8436741,-9.761203,99.99735,0.01796078,-0.0084389
102.4543,533.711,3.266466,-16.20216,-0.8459449,-9.791291,99.99879,0.01809046,-0.0084921
102.6377,534.6266,3.26505,-16.2717,-0.8481941,-9.82115,99.98272,0.01824087,-0.0085316
102.821,535.543,3.263668,-16.33866,-0.850296,-9.849321,100.0006,0.01834192,-0.0085603
103.0043,536.46,3.262191,-16.40339,-0.8522706,-9.876043,100.0225,0.01845277,-0.0085917
103.1877,537.3742,3.260825,-16.47175,-0.854422,-9.904816,100.009,0.01851682,-0.0086256
103.371,538.2938,3.259326,-16.54101,-0.8566011,-9.933925,99.99569,0.01856888,-0.0086719
103.5543,539.2142,3.257794,-16.60726,-0.8586148,-9.961119,100.0088,0.01872628,-0.0087336
103.7377,540.1348,3.256331,-16.6768,-0.8607828,-9.990119,100.0043,0.01888539,-0.0088058
103.921,541.0484,3.254838,-16.74695,-0.8629762,-10.01943,100.0838,0.0190838,-0.0088627
104.1043,541.9664,3.253297,-16.81982,-0.8652912,-10.05017,99.97988,0.01931344,-0.0088903
104.2877,542.8854,3.251809,-16.8902,-0.8674658,-10.07931,99.98098,0.01949169,-0.0089335
104.471,543.802,3.250234,-16.96125,-0.8696655,-10.10874,100.0013,0.01974655,-0.0089799
104.6543,544.7172,3.24871,-17.03258,-0.871867,-10.13822,100.0615,0.01997275,-0.0090029
104.8377,545.6336,3.247036,-17.10242,-0.8739804,-10.1667,100.0099,0.02022047,-0.009013
105.021,546.554,3.245481,-17.17001,-0.8759625,-10.19368,100.0191,0.02050852,-0.0090169
105.2043,547.4692,3.243854,-17.24539,-0.8783313,-10.22517,100.0021,0.02075835,-0.0090181
105.3877,548.3899,3.242127,-17.31921,-0.8806046,-10.25557,99.99734,0.02104296,-0.0090293
105.571,549.3058,3.24062,-17.38863,-0.8826476,-10.28331,100.0279,0.0213048,-0.0090533
105.7543,550.2246,3.238886,-17.46008,-0.8847801,-10.3121,99.96106,0.02155416,-0.0090873
105.9377,551.1422,3.237104,-17.53191,-0.8869201,-10.34101,99.97813,0.0218488,-0.0091061
106.121,552.0572,3.23537,-17.60189,-0.8889599,-10.36876,99.97689,0.02211066,-0.0090912
106.3043,552.9765,3.233482,-17.67406,-0.8910903,-10.3976,99.99061,0.02233715,-0.0090679
106.4876,553.8965,3.231879,-17.74804,-0.8932986,-10.42737,99.99842,0.02259337,-0.0090479
106.671,554.8132,3.230065,-17.8209,-0.8954461,-10.45644,100.0012,0.02283312,-0.0090002
106.8543,555.7294,3.228247,-17.89322,-0.8975574,-10.48508,100.0006,0.02308535,-0.0089016
107.0377,556.6437,3.22647,-17.96403,-0.8995828,-10.51276,99.99039,0.0232982,-0.0087603
107.221,557.5611,3.224611,-18.03066,-0.9013866,-10.53786,99.99999,0.02353786,-0.0085808
107.4043,558.4824,3.2227,-18.10076,-0.9033531,-10.56482,100.0117,0.02376769,-0.0083942
107.5877,559.397,3.220722,-18.16884,-0.9052172,-10.59058,99.94598,0.02398135,-0.0082158
107.771,560.318,3.21878,-18.22928,-0.9066891,-10.61176,100.032,0.02417031,-0.0080363
107.9543,561.2309,3.217,-18.28945,-0.9081476,-10.63279,99.98734,0.02435767,-0.0078613
108.1377,562.1555,3.214926,-18.3506,-0.9096306,-10.65415,100.125,0.02448031,-0.0076448
108.321,563.0726,3.213166,-18.41337,-0.9111925,-10.67643,99.98926,0.0245059,-0.0074079
108.5043,563.9886,3.211068,-18.47329,-0.9126074,-10.697,99.97141,0.02445656,-0.0071674
108.6877,564.9068,3.209137,-18.5303,-0.9138703,-10.71579,100.0012,0.02445451,-0.0069134
108.871,565.8238,3.207171,-18.58582,-0.9150504,-10.73364,100.0006,0.02450864,-0.0066117
109.0543,566.7472,3.205252,-18.63407,-0.9158619,-10.74717,99.98816,0.0244697,-0.0062509
109.2376,567.6669,3.203383,-18.68362,-0.9167316,-10.7614,100.0332,0.02442044,-0.0058532
109.421,568.5805,3.201448,-18.72956,-0.917427,-10.77357,100.0186,0.02434756,-0.005443
109.6043,569.5037,3.199564,-18.77094,-0.917882,-10.78294,100.0027,0.02431799,-0.0050385
109.7877,570.4224,3.197478,-18.81128,-0.9182884,-10.79172,99.99238,0.02434323,-0.0046545
109.971,571.3408,3.195644,-18.84322,-0.9182797,-10.79564,99.99251,0.0244144,-0.0042917
110.1543,572.2618,3.193749,-18.87567,-0.9182876,-10.79977,100.0646,0.0244962,-0.003931
110.3377,573.1811,3.191788,-18.90288,-0.9180401,-10.80088,100.027,0.02455482,-0.0036086
110.521,574.1052,3.189865,-18.93023,-0.9177887,-10.80196,100.0274,0.02460281,-0.0033424
110.7043,575.0234,3.187825,-18.95659,-0.9174934,-10.8025,99.99045,0.02461374,-0.0031217
110.8877,575.9416,3.185892,-18.97807,-0.9169601,-10.80024,99.99032,0.02463753,-0.0029615
111.071,576.8629,3.183863,-19.00039,-0.9164618,-10.79838,100.023,0.0246665,-0.0028514
111.2543,577.7904,3.18195,-19.02032,-0.9158351,-10.79503,99.99499,0.02457953,-0.0027929
111.4377,578.7033,3.18,-19.04271,-0.9153509,-10.79326,99.98016,0.02446985,-0.0027994
111.621,579.6228,3.178094,-19.06159,-0.9146826,-10.78935,100.0777,0.02431453,-0.0028748
111.8043,580.5387,3.176218,-19.08227,-0.9141051,-10.78649,99.95025,0.02426657,-0.0030281
111.9876,581.4597,3.174182,-19.10592,-0.9136618,-10.78522,100.0099,0.02430039,-0.0032363
112.171,582.386,3.172363,-19.13012,-0.9132312,-10.78412,99.98879,0.02428511,-0.003463
112.3543,583.303,3.170431,-19.15932,-0.9130492,-10.78593,100.0101,0.02416574,-0.0036302
112.5377,584.2253,3.168626,-19.19139,-0.9129981,-10.78928,100.0169,0.02397289,-0.0037229
112.721,585.1432,3.166558,-19.22494,-0.913018,-10.79346,100.0077,0.0236424,-0.0037594
112.9043,586.062,3.164506,-19.26081,-0.913143,-10.7989,100.0317,0.02317,-0.0038178
113.0877,586.9834,3.162678,-19.29793,-0.9134108,-10.80603,99.98666,0.02269884,-0.0039577
113.271,587.902,3.161004,-19.32022,-0.9140284,-10.8173,99.98032,0.02215571,-0.0041472
113.4543,588.8196,3.159244,-19.34107,-0.9146256,-10.82832,99.99762,0.0216262,-0.0043848
113.6377,589.7431,3.157617,-19.36894,-0.9155535,-10.84328,99.99532,0.02100905,-0.0046622
113.821,590.6562,3.156077,-19.4063,-0.9169335,-10.86358,99.97524,0.02047822,-0.0049771
114.0043,591.5759,3.154479,-19.45849,-0.9190144,-10.89221,100.0191,0.02012136,-0.0053337
114.1877,592.4954,3.152872,-19.50856,-0.9209919,-10.91965,99.95778,0.01996512,-0.0056185
114.371,593.4122,3.151162,-19.55839,-0.9229592,-10.94695,100.0153,0.01982502,-0.0059181
114.5543,594.3328,3.14982,-19.60615,-0.9248259,-10.97309,100.0042,0.01970453,-0.0061536
114.7376,595.2502,3.148308,-19.65272,-0.9266345,-10.99856,100.0055,0.01958646,-0.006254
114.921,596.1679,3.146812,-19.70503,-0.928714,-11.02726,99.94629,0.0193511,-0.0062275
114.9876,596.4969,3.146302,-19.72591,-0.9295582,-11.03874,99.95171,0.01925825,-0.0062128