File: data/Cable PVC 10C/Cable PVC 10C DATA_filtered.csv
Time (min),Temperature (°C),Weight (mg),Heat Flow (mW),Temperature Difference (°C),Temperature Difference (µV),Sample Purge Flow (mL/min),Deriv. Weight (%/°C),Deriv. Heat Flow (W/(g·°C))
0.002266666,33.09221,9.855736,-4.570933,-0.2198878,-1.425526,100.012,0.001620227,0.01046865
0.096,33.0563,9.856109,-4.569286,-0.2196869,-1.4241,100.006,0.001620591,0.01047299
0.196,33.04925,9.856314,-4.563593,-0.2189422,-1.41913,100.0014,0.001620662,0.01047384
0.296,33.08753,9.855976,-4.54469,-0.2163628,-1.402542,100.0146,0.001620274,0.01046922
0.396,33.1991,9.856114,-4.508873,-0.2114469,-1.371089,99.99722,0.001596318,0.01033916
0.496,33.41036,9.856007,-4.458139,-0.2044386,-1.326494,100.0156,0.001513792,0.009973028
0.596,33.71448,9.855756,-4.399826,-0.1963263,-1.27518,100.0217,0.001398728,0.009501774
0.696,34.1309,9.855751,-4.337474,-0.1876023,-1.220249,100.005,0.001280771,0.009045429
0.796,34.65566,9.855334,-4.27863,-0.1792904,-1.168314,99.98453,0.001116649,0.008412905
0.896,35.29261,9.855625,-4.223196,-0.1713725,-1.119275,100.0026,0.000962133,0.007731756
0.996,36.02869,9.855585,-4.175472,-0.164449,-1.076919,100.0335,0.000787745,0.007022208
1.096,36.86668,9.855359,-4.13903,-0.1589963,-1.044377,99.96332,0.000555554,0.006301196
1.196,37.7991,9.855399,-4.110152,-0.154518,-1.018389,99.98976,0.000425125,0.005644718
1.296,38.79868,9.855484,-4.091406,-0.1514019,-1.001224,99.97095,-0.00028735,0.002641778
1.396,39.86891,9.855566,-4.080765,-0.1493389,-0.9911089,100.0041,-0.00047187,0.001219675
1.496,40.98721,9.855712,-4.078528,-0.1483611,-0.9883165,99.97978,-0.00073744,0.000213802
1.596,42.16016,9.855872,-4.083917,-0.148362,-0.9921741,99.9943,-0.00084389,-0.0005126
1.696,43.35244,9.855826,-4.0965,-0.1492766,-1.002305,99.98014,-0.0009627,-0.0011177
1.796,44.56864,9.855851,-4.115288,-0.1509817,-1.017865,99.99962,-0.0010245,-0.0016141
1.896,45.7834,9.856241,-4.138428,-0.1532255,-1.037224,99.99982,-0.00086718,-0.002022
1.996,47.00881,9.856192,-4.166078,-0.1560341,-1.060539,99.96634,-0.00080854,-0.002373
2.096,48.21616,9.856476,-4.196906,-0.1592306,-1.086642,100.0018,-0.00062775,-0.0026488
2.196,49.41862,9.856548,-4.23087,-0.1628081,-1.115501,99.9952,-0.00043478,-0.0028774
2.296,50.58904,9.85632,-4.267144,-0.1666638,-1.146398,99.98361,-0.00023904,-0.0030577
2.396,51.76018,9.856444,-4.30249,-0.1703859,-1.176497,100.0379,-6.8323e-05,-0.0031839
2.496,52.89138,9.856508,-4.339531,-0.1743064,-1.208097,99.99755,-7.4493e-05,-0.0032713
2.596,54.00952,9.856324,-4.37743,-0.1783226,-1.240466,99.98428,-0.0001414,-0.0033094
2.696,55.09716,9.856574,-4.413644,-0.182117,-1.27138,99.98866,-0.00021924,-0.0032926
2.796,56.16158,9.85632,-4.449096,-0.1858048,-1.301642,100.0051,-0.00013066,-0.0032237
2.896,57.19502,9.856566,-4.483862,-0.1894019,-1.331324,99.95801,-0.00017263,-0.0030965
2.996,58.21055,9.856582,-4.51632,-0.1927266,-1.359002,100.0246,-0.00018054,-0.0029054
3.096,59.21122,9.856589,-4.543842,-0.1954709,-1.382369,99.98594,-9.6662e-05,-0.0026723
3.196,60.1843,9.856488,-4.57107,-0.1981728,-1.405489,99.97879,-3.9441e-05,-0.0024163
3.296,61.14756,9.856489,-4.5931,-0.2002302,-1.424066,100.0393,9.8895e-05,-0.0021025
3.396,62.10232,9.856638,-4.612264,-0.2019329,-1.440141,99.98751,0.000304422,-0.0017863
3.496,63.04658,9.856632,-4.626352,-0.2030116,-1.451776,99.97582,0.00031393,-0.0014497
3.596,63.97758,9.856454,-4.639404,-0.2039598,-1.462503,100.0169,0.000419152,-0.0011316
3.696,64.90613,9.856454,-4.646975,-0.2042464,-1.46844,100.004,0.000455177,-0.00082467
3.796,65.82529,9.856234,-4.652025,-0.2042277,-1.47217,100.006,0.000523082,-0.00054274
3.896,66.75451,9.856262,-4.656003,-0.2040753,-1.474956,100.0059,0.000612058,-0.00027476
3.996,67.68184,9.856426,-4.655617,-0.2033984,-1.47392,100.0351,0.000626636,-5.466e-05
4.096,68.61096,9.856152,-4.653498,-0.202512,-1.471361,99.97929,0.000519016,0.000134926
4.196,69.53974,9.856278,-4.650816,-0.2015654,-1.468311,100.0157,0.000537774,0.000272364
4.296,70.47866,9.856101,-4.646634,-0.2004318,-1.463933,99.99462,0.000452016,0.000374616
4.396,71.43244,9.856041,-4.640705,-0.1990938,-1.458023,99.98809,0.000541641,0.000436301
4.496,72.38188,9.855906,-4.636148,-0.1979242,-1.453312,99.96792,0.000570237,0.00046258
4.596,73.34728,9.856157,-4.63057,-0.1966329,-1.447699,99.99906,0.00052239,0.000459777
4.696,74.31906,9.855841,-4.626914,-0.1955708,-1.443764,100.0443,0.000681771,0.000428448
4.796,75.29863,9.856006,-4.622331,-0.1943994,-1.43901,99.97866,0.000551582,0.000383854
4.896,76.28368,9.855663,-4.618272,-0.1932898,-1.434708,100.0706,0.000419296,0.000321209
4.996,77.28114,9.855845,-4.614634,-0.1922331,-1.430772,99.97955,0.00044412,0.000245599
5.096,78.27685,9.855582,-4.614348,-0.1915931,-1.42977,100.0277,0.000460311,0.000170436
5.196,79.29026,9.855499,-4.611589,-0.1906836,-1.426587,99.99648,0.000403121,9.17188e-05
5.296,80.306,9.855851,-4.610876,-0.1900166,-1.425196,100.0255,0.000364863,-2.0116e-06
5.396,81.3219,9.855678,-4.612488,-0.1896224,-1.425842,100.0204,0.000436934,-9.5146e-05
5.496,82.34726,9.855506,-4.61307,-0.1891067,-1.42558,99.98345,0.000563614,-0.00018685
5.596,83.37528,9.855462,-4.615248,-0.188778,-1.426715,99.99869,0.000525192,-0.00027152
5.696,84.40086,9.855474,-4.619088,-0.188643,-1.429308,100.0089,0.000641485,-0.00036495
5.796,85.42496,9.855338,-4.624315,-0.1886668,-1.433113,100.0056,0.000603779,-0.00044386
5.896,86.45382,9.855234,-4.628791,-0.1886052,-1.436262,100.0039,0.000395508,-0.000517
5.996,87.49081,9.855243,-4.63357,-0.1885764,-1.439672,100.0197,0.000206264,-0.00058904
6.096,88.50579,9.855328,-4.640519,-0.1888002,-1.444991,100.0186,7.21633e-05,-0.00064401
6.196,89.53184,9.855181,-4.647814,-0.1890601,-1.450609,99.93334,8.08836e-06,-0.00069738
6.296,90.55525,9.855251,-4.65517,-0.189327,-1.456283,100.0003,-4.3913e-05,-0.00074027
6.396,91.57741,9.855401,-4.662484,-0.1895916,-1.461926,99.98106,5.48266e-06,-0.00077305
6.496,92.59571,9.855361,-4.670998,-0.1899899,-1.468618,99.99274,0.000103042,-0.0007952
6.596,93.61449,9.855376,-4.679448,-0.1903775,-1.475252,99.98168,0.000136001,-0.00079676
6.696,94.6296,9.854999,-4.6886,-0.1908462,-1.482506,100.0089,0.000218748,-0.00079132
6.796,95.63666,9.855345,-4.695757,-0.1910897,-1.488016,100.0202,0.000465241,-0.00077709
6.896,96.64416,9.855172,-4.704209,-0.1914812,-1.494664,99.99744,0.000502229,-0.00075657
6.996,97.64655,9.85507,-4.711372,-0.1917284,-1.500184,100.0333,0.000488878,-0.00072594
7.096,98.65187,9.855218,-4.717766,-0.1919201,-1.505029,99.9608,0.00041246,-0.00068438
7.196,99.64839,9.854938,-4.724448,-0.1921547,-1.510131,99.97702,0.000445516,-0.00064358
7.296,100.647,9.854902,-4.730824,-0.1923561,-1.514967,99.96241,0.000386003,-0.00059484
7.396,101.6426,9.854942,-4.737802,-0.1926221,-1.520327,100.0008,0.000242065,-0.00054064
7.496,102.6394,9.854892,-4.741803,-0.1925591,-1.523084,99.99576,0.0001919,-0.00049452
7.596,103.6374,9.854858,-4.747031,-0.192631,-1.526912,100.0188,0.000149178,-0.0004474
7.696,104.641,9.854786,-4.751238,-0.1925889,-1.529845,99.9923,0.000143007,-0.00039973
7.796,105.6362,9.855074,-4.7535,-0.1923344,-1.531074,99.98797,0.00032666,-0.00035663
7.896,106.6313,9.854972,-4.756164,-0.1921258,-1.532658,99.9873,0.00046292,-0.00032933
7.996,107.6324,9.854728,-4.760809,-0.1921328,-1.535974,100.0224,0.000538254,-0.00030872
8.096,108.6255,9.854786,-4.762676,-0.1918381,-1.536859,99.96219,0.000593064,-0.00029756
8.196,109.6283,9.854488,-4.765506,-0.1916489,-1.538586,100.0011,0.000840828,-0.00028166
8.296,110.6252,9.854664,-4.768299,-0.1914562,-1.54028,100.0331,0.000912067,-0.00026811
8.396,111.6173,9.854474,-4.771289,-0.1912871,-1.542149,99.99382,0.000820584,-0.00025281
8.496001,112.615,9.854495,-4.773123,-0.1909924,-1.543004,100.0099,0.000644755,-0.00023744
8.596,113.6106,9.854335,-4.776717,-0.1908899,-1.545401,100.0167,0.000535795,-0.00022985
8.696,114.617,9.854113,-4.777776,-0.1905114,-1.545573,99.99972,0.000396449,-0.00021929
8.795999,115.623,9.854225,-4.779138,-0.1901662,-1.54601,100.0273,0.000384968,-0.00021604
8.896,116.621,9.854318,-4.781976,-0.1899823,-1.547741,99.96632,0.000293567,-0.00021321
8.996001,117.6292,9.854311,-4.783795,-0.1896876,-1.548575,100.0131,0.000259119,-0.0002159
9.096,118.6348,9.854181,-4.785739,-0.1894337,-1.54952,99.99122,0.000180806,-0.00023289
9.196,119.6391,9.854071,-4.78823,-0.1892486,-1.550946,99.99014,0.000305906,-0.00025359
9.295999,120.6398,9.854249,-4.790736,-0.1890638,-1.552382,100.009,0.000444064,-0.0002744
9.396,121.6437,9.853991,-4.793041,-0.188861,-1.553647,99.97588,0.000565354,-0.00030053
9.496001,122.6434,9.854032,-4.796694,-0.1888014,-1.556091,100.0227,0.000655035,-0.00033365
9.596,123.6526,9.854061,-4.799438,-0.1886449,-1.557738,100.0012,0.000649889,-0.00036911
9.696,124.658,9.853838,-4.803754,-0.1886549,-1.560761,100.0487,0.000725236,-0.00040195
9.795999,125.6623,9.853909,-4.807637,-0.1886189,-1.563405,99.996,0.00086272,-0.00044124
9.896,126.6694,9.853605,-4.812446,-0.1886806,-1.56686,100.0275,0.000783597,-0.00046265
9.996001,127.6741,9.853706,-4.818198,-0.1888431,-1.571144,99.96574,0.000873161,-0.0004819
10.096,128.6798,9.853647,-4.822,-0.1887986,-1.573717,100.029,0.000778183,-0.00050039
10.196,129.6838,9.85332,-4.828064,-0.1889927,-1.578275,99.97111,0.00077787,-0.00051975
10.296,130.6876,9.853409,-4.832708,-0.1890367,-1.581586,100.0,0.000844808,-0.00053444
10.396,131.6878,9.853331,-4.837241,-0.1890712,-1.584804,99.98103,0.000828627,-0.00054262
10.496,132.6904,9.853293,-4.843458,-0.1892788,-1.589494,99.97712,0.000955716,-0.00054874
10.596,133.6936,9.853166,-4.84864,-0.1893792,-1.59328,100.043,0.000984498,-0.00055317
10.696,134.6944,9.853038,-4.854634,-0.1895649,-1.597778,100.0544,0.001015506,-0.00055772
10.796,135.6974,9.853009,-4.86067,-0.1897531,-1.602311,99.98614,0.001166244,-0.00056802
10.896,136.6926,9.852765,-4.866109,-0.189879,-1.606322,99.95819,0.001254947,-0.00056742
10.996,137.6952,9.852656,-4.870227,-0.1898718,-1.60918,100.0119,0.001442933,-0.00056382
11.096,138.7004,9.852616,-4.876714,-0.190128,-1.614106,100.0078,0.001543754,-0.00055793
11.196,139.7001,9.852593,-4.882727,-0.1903428,-1.618622,100.0113,0.001724464,-0.00055882
11.296,140.7006,9.852149,-4.888622,-0.1905438,-1.623031,100.0655,0.001891407,-0.00056617
11.396,141.7014,9.852142,-4.89387,-0.190679,-1.626876,100.0512,0.002013516,-0.00057109
11.496,142.699,9.851671,-4.898681,-0.1907684,-1.630337,100.0078,0.00216574,-0.00057575
11.596,143.7074,9.851626,-4.904489,-0.1909594,-1.634673,100.0006,0.002364547,-0.00057904
11.696,144.7076,9.851406,-4.909829,-0.1911018,-1.638597,100.003,0.00245485,-0.00057916
11.796,145.7032,9.851105,-4.916446,-0.1913745,-1.643641,99.99706,0.002501723,-0.00058451
11.896,146.7069,9.850919,-4.922416,-0.1915803,-1.648118,100.0098,0.002688675,-0.00058622
11.996,147.6992,9.850645,-4.927784,-0.191724,-1.652068,100.0031,0.00288942,-0.00058332
12.096,148.7049,9.850324,-4.933872,-0.191942,-1.656651,99.99493,0.003173658,-0.00057405
12.196,149.7071,9.850006,-4.939266,-0.192086,-1.660621,100.0228,0.0035674,-0.00057407
12.296,150.711,9.849641,-4.945198,-0.1922859,-1.665065,99.9697,0.003935656,-0.00057207
12.396,151.7085,9.849366,-4.950793,-0.1924505,-1.669213,99.94545,0.004254166,-0.00057238
12.496,152.7102,9.848739,-4.954911,-0.1924656,-1.672067,99.97074,0.00454855,-0.00058021
12.596,153.71,9.848441,-4.961518,-0.1927307,-1.677102,100.0089,0.004938721,-0.00059516
12.696,154.7194,9.847618,-4.968391,-0.1930216,-1.682369,100.0189,0.005305246,-0.0006122
12.796,155.7226,9.847362,-4.972774,-0.1930594,-1.685449,100.0453,0.005493046,-0.0006333
12.896,156.7196,9.846728,-4.980141,-0.1933984,-1.691149,100.0034,0.005759262,-0.00065481
12.996,157.7276,9.846186,-4.98611,-0.1935982,-1.695625,100.0247,0.0060403,-0.00067232
13.096,158.7268,9.845516,-4.993524,-0.1939624,-1.701369,100.0285,0.006385963,-0.00068981
13.196,159.7295,9.844781,-5.000288,-0.1942642,-1.706541,100.0211,0.006816602,-0.00071173
13.296,160.726,9.844425,-5.007934,-0.1946525,-1.712486,100.0087,0.007437715,-0.00073214
13.396,161.7274,9.843434,-5.013938,-0.1948776,-1.716994,99.99744,0.007926446,-0.00075354
13.496,162.7268,9.842832,-5.022476,-0.1953537,-1.723724,99.99022,0.008239539,-0.00077652
13.596,163.7284,9.841806,-5.029618,-0.1956888,-1.729226,100.0428,0.008714156,-0.00079838
13.696,164.7309,9.840824,-5.037529,-0.1960989,-1.735404,99.99291,0.009108352,-0.00081894
13.796,165.7314,9.839862,-5.046378,-0.1966014,-1.742405,99.99381,0.009503142,-0.00084112
13.896,166.7297,9.839019,-5.054764,-0.1970568,-1.748999,99.99481,0.009706376,-0.0008617
13.996,167.7333,9.838136,-5.063562,-0.1975508,-1.755955,99.9961,0.009990082,-0.00088364
14.096,168.7276,9.837116,-5.071258,-0.1979368,-1.761947,100.0058,0.01020988,-0.00090409
14.196,169.7247,9.836219,-5.080726,-0.1984958,-1.769494,99.9909,0.01045126,-0.00091645
14.296,170.7236,9.834889,-5.089351,-0.1989706,-1.7763,100.0323,0.01093931,-0.00092312
14.396,171.7277,9.834024,-5.099188,-0.1995604,-1.784165,100.049,0.01131561,-0.00093522
14.496,172.727,9.832734,-5.109866,-0.200232,-1.792769,100.0649,0.01155009,-0.00094536
14.596,173.7234,9.831697,-5.118794,-0.2007307,-1.79984,99.9718,0.01190501,-0.00095868
14.696,174.7258,9.830458,-5.126592,-0.2011184,-1.805922,99.97014,0.01234866,-0.00097087
14.796,175.721,9.829181,-5.136582,-0.2017186,-1.813924,99.98064,0.01269227,-0.00098626
14.896,176.7234,9.828147,-5.14632,-0.2022911,-1.821704,100.0013,0.01297377,-0.00099954
14.996,177.7245,9.826684,-5.156015,-0.2028584,-1.829442,100.0262,0.01338493,-0.0010267
15.096,178.7284,9.825226,-5.167048,-0.2035739,-1.838358,99.98984,0.01385829,-0.0010632
15.196,179.7326,9.8238,-5.178424,-0.2043242,-1.84757,100.006,0.01430252,-0.0011022
15.296,180.7388,9.822608,-5.18793,-0.2048913,-1.855144,99.98266,0.01497094,-0.0011398
15.396,181.7386,9.821156,-5.199365,-0.2056438,-1.864409,99.98858,0.01562621,-0.0011792
15.496,182.7406,9.819444,-5.211075,-0.2064221,-1.873918,100.0169,0.01624404,-0.001214
15.596,183.7394,9.817862,-5.223816,-0.2072974,-1.884329,99.99291,0.01698514,-0.0012597
15.696,184.7384,9.816165,-5.236366,-0.208152,-1.894575,100.0316,0.01797919,-0.0013129
15.796,185.7424,9.814257,-5.249682,-0.2090783,-1.90549,100.0186,0.01895394,-0.0013676
15.896,186.7418,9.812462,-5.262876,-0.2099904,-1.9163,99.98497,0.01989796,-0.0014185
15.996,187.7411,9.810476,-5.276752,-0.2109652,-1.927706,100.003,0.02089685,-0.001468
16.096,188.7419,9.80853,-5.291222,-0.2119962,-1.939637,99.97481,0.02201018,-0.0015239
16.196,189.7348,9.806158,-5.306979,-0.2131468,-1.952694,99.99984,0.02306803,-0.00158
16.296,190.737,9.803812,-5.323542,-0.2143711,-1.966456,100.009,0.02427711,-0.0016287
16.396,191.7362,9.801378,-5.3394,-0.215525,-1.979602,100.0217,0.02566534,-0.0016649
16.496,192.7352,9.798874,-5.35598,-0.2167444,-1.993378,100.0217,0.02693865,-0.0016922
16.596,193.7316,9.796204,-5.373284,-0.2180302,-2.007791,99.95609,0.02810245,-0.0017128
16.696,194.7285,9.793345,-5.39137,-0.2193879,-2.022892,99.98058,0.02927486,-0.0017273
16.796,195.7336,9.79033,-5.407401,-0.220546,-2.036189,99.98707,0.03060633,-0.0017428
16.896,196.7301,9.787062,-5.424394,-0.2217922,-2.050328,100.0268,0.03211638,-0.00176
16.996,197.7274,9.784103,-5.442226,-0.2231169,-2.065206,100.0245,0.03331624,-0.001755
17.096,198.7222,9.780926,-5.459107,-0.2243656,-2.079249,100.0041,0.034714,-0.0017506
17.196,199.719,9.777418,-5.47632,-0.225647,-2.093584,99.93618,0.03620375,-0.0017424
17.296,200.7134,9.773465,-5.4955,-0.2269621,-2.108255,100.0165,0.03776658,-0.0017383
17.396,201.7135,9.770038,-5.512142,-0.2282327,-2.12255,99.99275,0.03951369,-0.0017276
17.496,202.7134,9.766153,-5.527696,-0.229415,-2.136055,99.99684,0.04109844,-0.0017147
17.596,203.7139,9.761602,-5.544566,-0.23073,-2.150825,99.97375,0.0427203,-0.0017016
17.696,204.714,9.7576,-5.559985,-0.2319182,-2.164441,100.0108,0.04437278,-0.0016909
17.796,205.7144,9.752768,-5.578723,-0.2334253,-2.181061,100.0216,0.04629972,-0.0016849
17.896,206.7106,9.748478,-5.594882,-0.2347014,-2.195549,99.97735,0.04844713,-0.0016948
17.996,207.7133,9.743847,-5.610869,-0.2359667,-2.209959,99.9825,0.05031812,-0.0016954
18.096,208.7178,9.738418,-5.627868,-0.2373356,-2.225393,100.0474,0.05194348,-0.0017014
18.196,209.7152,9.733292,-5.644939,-0.238721,-2.240996,99.96993,0.05368579,-0.0017021
18.296,210.7194,9.727707,-5.661306,-0.2400464,-2.256069,100.014,0.05573086,-0.0017093
18.396,211.7176,9.721878,-5.677966,-0.2414094,-2.271526,99.99278,0.05804444,-0.001721
18.496,212.7205,9.71629,-5.695171,-0.2428274,-2.287527,99.99738,0.06047055,-0.0017278
18.596,213.7265,9.711098,-5.712797,-0.2442908,-2.303995,99.99796,0.0631922,-0.0017405
18.696,214.7272,9.704518,-5.729675,-0.2456944,-2.319927,100.0318,0.0661253,-0.001753
18.796,215.7292,9.697676,-5.74741,-0.2471841,-2.336712,99.97803,0.06940625,-0.0017674
18.896,216.7373,9.690516,-5.76437,-0.248605,-2.352866,100.002,0.07305486,-0.0017869
18.996,217.7302,9.683041,-5.781711,-0.2500753,-2.369506,99.98069,0.07692754,-0.0017987
19.096,218.736,9.675399,-5.800434,-0.2516906,-2.387404,99.9754,0.08042675,-0.0018067
19.196,219.7385,9.667403,-5.818012,-0.2532123,-2.404402,99.99045,0.0837593,-0.0018077
19.296,220.7384,9.658884,-5.837304,-0.2548968,-2.42298,99.97876,0.08716892,-0.00181
19.396,221.7423,9.650016,-5.85503,-0.2564413,-2.440249,99.98842,0.09067936,-0.0018023
19.496,222.742,9.640962,-5.872239,-0.2579472,-2.457185,100.0169,0.09443579,-0.0017898
19.596,223.7421,9.631586,-5.889763,-0.2594888,-2.474501,99.94861,0.09811412,-0.0017819
19.696,224.7411,9.621736,-5.90707,-0.2610145,-2.491684,100.0186,0.1018398,-0.0017787
19.796,225.7445,9.611532,-5.92384,-0.262497,-2.508494,99.98364,0.1056057,-0.0017676
19.896,226.7462,9.600965,-5.941636,-0.2640776,-2.526272,100.0256,0.1095795,-0.001752
19.996,227.7407,9.590009,-5.959392,-0.2656604,-2.54409,100.0217,0.113599,-0.0017346
20.096,228.7392,9.578702,-5.977436,-0.2672715,-2.56221,100.0267,0.117862,-0.0017091
20.196,229.7349,9.567009,-5.994849,-0.2688336,-2.579896,100.1007,0.1222351,-0.0016798
20.296,230.735,9.554744,-6.01061,-0.2702512,-2.596228,99.99546,0.1268027,-0.001656
20.396,231.7318,9.542147,-6.024807,-0.2715356,-2.611302,99.99189,0.1315213,-0.0016215
20.496,232.7309,9.528898,-6.04044,-0.2729515,-2.627668,100.0255,0.1365681,-0.001594
20.596,233.7263,9.515369,-6.05629,-0.2743935,-2.644318,99.99072,0.1419281,-0.0015676
20.696,234.7242,9.501294,-6.07273,-0.2758904,-2.661522,100.0264,0.14726,-0.0015526
20.796,235.7205,9.486574,-6.087472,-0.2772417,-2.677346,99.94247,0.1526036,-0.0015366
20.896,236.7123,9.471431,-6.101494,-0.2785376,-2.692668,99.96949,0.1581383,-0.0015241
20.996,237.7113,9.455242,-6.117344,-0.2799942,-2.709551,100.0173,0.163728,-0.0015074
21.096,238.7092,9.438845,-6.132568,-0.281421,-2.726019,99.96569,0.1695196,-0.0014925
21.196,239.7062,9.422306,-6.145884,-0.2826888,-2.740928,100.0291,0.1756667,-0.0014806
21.296,240.7066,9.404812,-6.160436,-0.2840676,-2.756938,100.0043,0.1819568,-0.0014827
21.396,241.7049,9.386668,-6.175164,-0.2854676,-2.773183,99.97492,0.1886241,-0.0014969
21.496,242.7082,9.367975,-6.188904,-0.2867838,-2.788642,100.0006,0.1958296,-0.0015282
21.596,243.7061,9.348215,-6.204635,-0.2882803,-2.805885,100.0038,0.2038002,-0.0015695
21.696,244.7041,9.327886,-6.219199,-0.2896772,-2.822178,100.0012,0.2122928,-0.0016221
21.796,245.7027,9.306831,-6.235493,-0.291226,-2.839974,99.97516,0.2209501,-0.0016711
21.896,246.7024,9.284722,-6.25247,-0.2928377,-2.858422,100.0516,0.2299696,-0.0017315
21.996,247.7045,9.261634,-6.2714,-0.294617,-2.878533,99.97934,0.2389648,-0.0018004
22.096,248.6981,9.237462,-6.288385,-0.2962353,-2.897098,99.98009,0.2479131,-0.0018723
22.196,249.7006,9.212442,-6.306349,-0.2979355,-2.916498,99.99481,0.257142,-0.0019419
22.296,250.6932,9.18686,-6.32517,-0.2997152,-2.936707,99.96131,0.2663042,-0.0020101
22.396,251.6922,9.160224,-6.345386,-0.3016107,-2.95808,99.97881,0.2753619,-0.0020854
22.496,252.692,9.13293,-6.366894,-0.3036182,-2.980595,100.0002,0.2846288,-0.0021558
22.596,253.6884,9.104522,-6.38863,-0.305646,-3.003344,99.99792,0.2941553,-0.0022265
22.696,254.6902,9.075126,-6.41077,-0.3077045,-3.026429,99.96645,0.3040464,-0.0022942
22.796,255.6852,9.044735,-6.433794,-0.309844,-3.05036,100.0195,0.3137964,-0.0023575
22.896,256.6838,9.013648,-6.458318,-0.3121065,-3.07554,99.99476,0.3243684,-0.0024131
22.996,257.679,8.981088,-6.48067,-0.3141851,-3.098932,99.99305,0.3351416,-0.0024693
23.096,258.6814,8.947442,-6.506348,-0.316557,-3.125101,99.9937,0.3461456,-0.0025231
23.196,259.6874,8.912876,-6.530655,-0.3188178,-3.150183,99.98599,0.3576694,-0.0025714
23.296,260.686,8.876832,-6.55777,-0.321316,-3.17765,99.98941,0.3690225,-0.0026114
23.396,261.6896,8.839996,-6.583628,-0.323705,-3.204082,99.9852,0.3792382,-0.002624
23.496,262.6863,8.801822,-6.610586,-0.3261841,-3.231435,99.97944,0.3884631,-0.0025898
23.596,263.6835,8.762949,-6.63545,-0.3284824,-3.257026,99.96571,0.3966446,-0.0025108
23.696,264.6766,8.723242,-6.664156,-0.3311002,-3.285828,100.0035,0.4032676,-0.00241
23.796,265.6754,8.682593,-6.688134,-0.3333215,-3.310746,99.99934,0.4091238,-0.0022891
23.896,266.6752,8.642132,-6.709299,-0.3353041,-3.333318,99.98626,0.414335,-0.0021643
23.996,267.6648,8.601425,-6.72748,-0.337047,-3.35355,100.0103,0.419132,-0.0020495
24.096,268.6642,8.560197,-6.745585,-0.338776,-3.373666,99.99032,0.4241867,-0.001955
24.196,269.6631,8.518616,-6.763635,-0.3405032,-3.393805,100.004,0.4299541,-0.0018856
24.296,270.658,8.476313,-6.780918,-0.3421682,-3.413352,100.0241,0.437143,-0.0018864
24.396,271.6562,8.433275,-6.799475,-0.3439339,-3.433927,100.0161,0.4464287,-0.00195
24.496,272.655,8.389551,-6.817884,-0.3456848,-3.454382,100.0014,0.4580728,-0.0020677
24.596,273.6533,8.34452,-6.835997,-0.3474155,-3.474678,99.99266,0.4727307,-0.0022373
24.696,274.649,8.298485,-6.856434,-0.3493333,-3.49687,100.0198,0.490707,-0.0024728
24.796,275.6444,8.250272,-6.880644,-0.3515566,-3.522154,99.99637,0.5124992,-0.0027692
24.896,276.6424,8.199878,-6.90857,-0.354075,-3.550428,99.99999,0.5389612,-0.0031258
24.996,277.649,8.146322,-6.94071,-0.3569319,-3.58216,100.0118,0.5704039,-0.0035238
25.096,278.6441,8.089914,-6.976755,-0.360121,-3.617102,99.9882,0.606971,-0.0039395
25.196,279.6416,8.029905,-7.017585,-0.3636902,-3.655853,100.0574,0.6491339,-0.0043248
25.296,280.637,7.96554,-7.063656,-0.3676739,-3.69883,99.99501,0.6974169,-0.0046609
25.396,281.6276,7.895989,-7.114036,-0.3719947,-3.745256,100.0199,0.75375,-0.0049534
25.496,282.6222,7.821197,-7.166424,-0.3764644,-3.793258,100.0438,0.8208275,-0.0052524
25.596,283.6186,7.740111,-7.220759,-0.381078,-3.842784,100.0212,0.9016163,-0.0057105
25.696,284.6165,7.652068,-7.273803,-0.3855728,-3.891183,100.0062,0.9967766,-0.0065209
25.796,285.6086,7.555272,-7.326506,-0.390031,-3.939282,100.0073,1.10267,-0.0077629
25.896,286.6045,7.446368,-7.383892,-0.394848,-3.991083,99.97566,1.211926,-0.0092936
25.996,287.5999,7.322146,-7.460114,-0.4011495,-4.057976,100.017,1.314103,-0.01081645
26.096,288.5842,7.181602,-7.57575,-0.4105633,-4.156456,100.0128,1.398409,-0.01199574
26.196,289.57,7.028605,-7.735751,-0.423461,-4.290381,100.0135,1.456331,-0.01255565
26.296,290.5563,6.870395,-7.916725,-0.4379688,-4.440822,99.98491,1.481814,-0.01236004
26.396,291.5386,6.714392,-8.08026,-0.4510516,-4.577034,100.0008,1.473169,-0.01138835
26.496,292.5309,6.565665,-8.202556,-0.4608312,-4.679916,100.0012,1.433625,-0.0097185
26.596,293.5262,6.425844,-8.277368,-0.4668444,-4.744703,100.0272,1.370403,-0.0075543
26.696,294.5258,6.29541,-8.315402,-0.4699469,-4.779986,100.0179,1.295646,-0.0052846
26.796,295.5226,6.173478,-8.333828,-0.4715063,-4.799616,100.0194,1.210953,-0.0030849
26.896,296.523,6.05911,-8.343994,-0.472415,-4.812649,100.0341,1.124641,-0.0012184
26.996,297.5206,5.952123,-8.3487,-0.4728978,-4.82135,99.9803,1.03912,0.000325216
27.096,298.5214,5.853198,-8.344894,-0.472733,-4.823288,99.98974,0.9548866,0.001670637
27.196,299.527,5.763092,-8.3259,-0.4713969,-4.813196,100.015,0.8693326,0.003023554
27.296,300.5308,5.681676,-8.291375,-0.4688654,-4.790875,99.99575,0.789306,0.004382059
27.396,301.5394,5.6089,-8.240594,-0.4650844,-4.755746,99.99311,0.7125382,0.005794534
27.496,302.5462,5.543845,-8.171869,-0.4599354,-4.706563,99.99545,0.6411109,0.007190305
27.596,303.5564,5.485205,-8.091493,-0.4539066,-4.648295,99.99962,0.5759312,0.008497785
27.696,304.5637,5.432726,-7.998094,-0.4469016,-4.57993,99.97801,0.5173531,0.009645558
27.796,305.5752,5.385614,-7.89099,-0.4388692,-4.500924,100.0177,0.4654614,0.0106093
27.896,306.5813,5.34286,-7.774424,-0.4301534,-4.414802,100.0102,0.4196267,0.01134667
27.996,307.5952,5.304063,-7.652869,-0.4210817,-4.324878,100.0109,0.3789628,0.01186643
28.096,308.606,5.26951,-7.52564,-0.411615,-4.230758,99.98116,0.3427678,0.01216898
28.196,309.6156,5.237972,-7.398688,-0.4022116,-4.13715,100.0076,0.3105372,0.01225855
28.296,310.6316,5.20901,-7.272675,-0.3929111,-4.044454,100.0056,0.281709,0.01215497
28.396,311.6398,5.182986,-7.150144,-0.3839231,-3.95485,99.97843,0.2557642,0.01189418
28.496,312.6447,5.15938,-7.031397,-0.3752526,-3.86836,99.99098,0.2325654,0.01151215
28.596,313.6518,5.137922,-6.91585,-0.3668618,-3.784634,100.0004,0.2115439,0.01103403
28.696,314.6621,5.118282,-6.809064,-0.3591648,-3.707944,100.0071,0.192313,0.01048864
28.796,315.672,5.100346,-6.706504,-0.3518168,-3.634741,99.979,0.1748048,0.00990871
28.896,316.677,5.084074,-6.611515,-0.3450702,-3.567642,99.9839,0.1588491,0.009293059
28.996,317.6792,5.069546,-6.521949,-0.3387594,-3.504941,100.0325,0.1442647,0.008659484
29.096,318.69,5.056146,-6.440316,-0.333075,-3.448491,100.0178,0.1306897,0.008022392
29.196,319.688,5.044153,-6.364067,-0.3278247,-3.396422,100.0066,0.118247,0.007400112
29.296,320.6922,5.033306,-6.293426,-0.3230107,-3.348801,100.0251,0.1068114,0.006775192
29.396,321.6989,5.023383,-6.23011,-0.3187628,-3.306992,99.99071,0.09641816,0.00615775
29.496,322.7015,5.01461,-6.173286,-0.3150168,-3.270333,99.98402,0.08666593,0.00553574
29.596,323.6987,5.006772,-6.121347,-0.3116472,-3.237526,100.0015,0.07839866,0.004959297
29.696,324.7024,4.999597,-6.074331,-0.3086509,-3.208548,99.99969,0.07047622,0.004341536
29.796,325.7028,4.993294,-6.036824,-0.3063705,-3.186974,99.99515,0.0635388,0.003750798
29.896,326.7022,4.987334,-6.000593,-0.3041944,-3.166457,100.0294,0.05742058,0.003167976
29.996,327.701,4.982146,-5.97145,-0.3025484,-3.151428,99.98329,0.05259668,0.002645421
30.096,328.6992,4.977377,-5.949318,-0.3014266,-3.141847,99.97944,0.04761198,0.002074956
30.196,329.6998,4.972966,-5.932285,-0.3006804,-3.136162,100.0087,0.04354715,0.001585642
30.296,330.7022,4.969266,-5.922532,-0.3004658,-3.136012,99.99824,0.03970926,0.001101138
30.396,331.6985,4.965308,-5.913874,-0.3003378,-3.136768,99.98134,0.03652057,0.000687059
30.496,332.7013,4.96191,-5.911792,-0.3006845,-3.142482,99.99879,0.03364674,0.000302102
30.596,333.7018,4.959013,-5.91035,-0.30108,-3.148716,99.9858,0.03119553,-9.0031e-06
30.696,334.7016,4.956208,-5.913457,-0.3018006,-3.158352,99.99492,0.0291384,-0.00027518
30.796,335.6984,4.953342,-5.91813,-0.3026322,-3.16916,99.97816,0.0273036,-0.00049321
30.896,336.7022,4.950958,-5.924816,-0.3036046,-3.181462,100.0246,0.02561321,-0.00071113
30.996,337.7024,4.948298,-5.933648,-0.3047254,-3.19532,100.0189,0.02430593,-0.0008724
31.096,338.7028,4.94608,-5.942608,-0.3058612,-3.209272,100.0341,0.02317852,-0.0010116
31.196,339.7019,4.943869,-5.954404,-0.3071956,-3.2253,100.0026,0.02205285,-0.0011233
31.296,340.6998,4.941967,-5.967438,-0.3086105,-3.242186,100.0036,0.02107432,-0.001213
31.396,341.6942,4.939568,-5.979268,-0.3099324,-3.258111,100.0098,0.01979886,-0.0012819
31.496,342.6985,4.937962,-5.992309,-0.3113339,-3.2749,99.9742,0.01859013,-0.0013405
31.596,343.6966,4.935982,-6.00627,-0.3127942,-3.292322,99.97453,0.01780592,-0.001388
31.696,344.693,4.934126,-6.019889,-0.3142222,-3.309424,100.0032,0.01718112,-0.0014236
31.796,345.6922,4.932582,-6.034457,-0.3157082,-3.327152,100.0216,0.01653387,-0.0014555
31.896,346.6885,4.932172,-6.04824,-0.3171296,-3.344216,99.97531,0.01599418,-0.0014922
31.996,347.6878,4.929781,-6.063244,-0.3186317,-3.362158,100.0458,0.01546324,-0.0015235
32.096,348.6836,4.928011,-6.079656,-0.3202217,-3.381038,100.0001,0.01504575,-0.0015564
32.196,349.6781,4.926666,-6.093966,-0.3216553,-3.398288,99.99374,0.01470203,-0.0015949
32.296,350.6758,4.925149,-6.10962,-0.323175,-3.41647,100.0261,0.01415871,-0.0016283
32.396,351.6818,4.92375,-6.126301,-0.3247583,-3.435356,99.98219,0.0137589,-0.0016693
32.496,352.6796,4.922672,-6.14217,-0.3262744,-3.453541,99.9842,0.01301971,-0.0017193
32.596,353.6799,4.921303,-6.15963,-0.327894,-3.472847,100.0403,0.01268279,-0.0017685
32.696,354.673,4.9201,-6.177035,-0.3295032,-3.492061,100.0232,0.01258722,-0.0018232
32.796,355.672,4.919566,-6.194024,-0.3310704,-3.51085,100.0116,0.01242886,-0.0018747
32.896,356.6687,4.917646,-6.214488,-0.332868,-3.532097,99.95809,0.01227744,-0.0019236
32.996,357.6728,4.916502,-6.232889,-0.3345156,-3.551786,99.95098,0.01210475,-0.0019653
33.096,358.666,4.915336,-6.253627,-0.3363277,-3.573142,100.0059,0.01195106,-0.0020152
33.196,359.665,4.914002,-6.273816,-0.338092,-3.59399,100.0041,0.01183791,-0.0020637
33.296,360.6631,4.913048,-6.293174,-0.3397867,-3.614114,100.0149,0.01154399,-0.002102
33.396,361.659,4.911942,-6.313867,-0.3415675,-3.635179,100.034,0.01131364,-0.0021275
33.496,362.6561,4.910885,-6.335003,-0.3433672,-3.656462,99.99812,0.01119772,-0.0021594
33.596,363.6494,4.909895,-6.35891,-0.3453493,-3.679712,100.0042,0.0110797,-0.0021863
33.696,364.6476,4.908686,-6.37885,-0.3470482,-3.69997,100.0311,0.01108378,-0.0022099
33.796,365.642,4.907502,-6.401618,-0.3489324,-3.72222,99.9985,0.01113764,-0.0022326
33.896,366.639,4.906425,-6.421829,-0.3506314,-3.74252,99.97475,0.01105124,-0.002252
33.996,367.6391,4.905424,-6.444872,-0.3525154,-3.764824,99.9954,0.01110051,-0.0022755
34.096,368.6336,4.904395,-6.467782,-0.3543818,-3.786956,99.99018,0.01108087,-0.0023159
34.196,369.6302,4.90321,-6.488974,-0.3561232,-3.80778,100.0016,0.01106672,-0.0023624
34.296,370.629,4.902184,-6.51187,-0.3579682,-3.82973,99.99585,0.0112357,-0.0024147
34.396,371.6266,4.90115,-6.53651,-0.3599245,-3.852899,99.98843,0.01135486,-0.0024711
34.496,372.6292,4.899797,-6.561951,-0.361923,-3.876546,99.98066,0.01157885,-0.0025279
34.596,373.6289,4.898937,-6.587192,-0.3639006,-3.899996,100.0066,0.01168082,-0.002597
34.696,374.6262,4.897556,-6.612385,-0.3658654,-3.923328,100.0264,0.01188135,-0.0026601
34.796,375.6244,4.896454,-6.639239,-0.3679324,-3.947784,100.0088,0.01219318,-0.0027137
34.896,376.6238,4.895319,-6.665909,-0.3699758,-3.972008,100.0182,0.01237742,-0.0027551
34.996,377.6195,4.89396,-6.694078,-0.3721115,-3.997247,100.0182,0.01258372,-0.0027906
35.096,378.6206,4.8929,-6.722007,-0.3742284,-4.022229,100.0196,0.01282178,-0.0028242
35.196,379.6176,4.891531,-6.750244,-0.3763595,-4.047356,100.006,0.0129801,-0.0028455
35.296,380.6162,4.890089,-6.779418,-0.3785426,-4.073068,100.0203,0.01315073,-0.0028632
35.396,381.6152,4.888926,-6.806151,-0.3805545,-4.096963,100.014,0.01327234,-0.002872
35.496,382.6118,4.887537,-6.834134,-0.38264,-4.121671,100.0542,0.01337123,-0.0028777
35.596,383.614,4.886238,-6.862894,-0.3847672,-4.14686,99.99035,0.01346888,-0.0028879
35.696,384.608,4.884957,-6.892036,-0.3869145,-4.17229,99.99139,0.01356218,-0.0028907
35.796,385.6089,4.883642,-6.919829,-0.38896,-4.196648,100.0052,0.01372056,-0.0028899
35.896,386.6,4.88221,-6.949799,-0.3911403,-4.22247,99.98082,0.01385286,-0.0028914
35.996,387.6006,4.880906,-6.976626,-0.3931043,-4.245994,99.99985,0.01404587,-0.0028851
36.096,388.6022,4.879532,-7.006836,-0.3952828,-4.271864,99.99459,0.01425033,-0.0028664
36.196,389.6006,4.878024,-7.033651,-0.3972297,-4.29525,99.97231,0.01452937,-0.0028455
36.296,390.5958,4.876763,-7.06227,-0.3992899,-4.31989,99.96239,0.0147422,-0.0028273
36.396,391.5938,4.87516,-7.090363,-0.4013028,-4.344034,100.0187,0.01512751,-0.0028022
36.496,392.5915,4.873722,-7.117141,-0.4032216,-4.367176,99.98656,0.01543174,-0.002789
36.596,393.5865,4.872262,-7.142276,-0.4050299,-4.389153,99.96328,0.01578806,-0.0027734
36.696,394.5885,4.870575,-7.172354,-0.407146,-4.41449,99.99956,0.01630901,-0.0027507
36.796,395.5848,4.868984,-7.197588,-0.4089446,-4.436406,100.0167,0.01692628,-0.0027299
36.896,396.5792,4.867264,-7.22503,-0.4108787,-4.45981,99.99959,0.01747734,-0.002713
36.996,397.5773,4.865806,-7.253372,-0.4128594,-4.483738,100.0023,0.01805424,-0.0027103
37.096,398.575,4.8639,-7.27799,-0.4146034,-4.505047,99.99753,0.01849888,-0.0027013
37.196,399.5706,4.861875,-7.303348,-0.4163922,-4.526832,99.98858,0.01916662,-0.0026853
37.296,400.5666,4.859897,-7.330678,-0.4182978,-4.549903,100.0551,0.01977846,-0.0026763
37.396,401.5694,4.858036,-7.356544,-0.4201036,-4.571922,100.0732,0.02040126,-0.0026623
37.496,402.5652,4.856055,-7.384063,-0.4220085,-4.595032,99.9597,0.02099914,-0.0026481
37.596,403.5641,4.854109,-7.409334,-0.4237631,-4.616531,99.97662,0.02164934,-0.0026425
37.696,404.5607,4.851538,-7.43585,-0.4255906,-4.638841,99.99272,0.02247016,-0.0026271
37.796,405.5586,4.849584,-7.461435,-0.4273512,-4.660446,100.0032,0.02341697,-0.0026101
37.896,406.5614,4.84737,-7.486156,-0.4290473,-4.681366,99.96496,0.02466638,-0.0025889
37.996,407.5555,4.84499,-7.512174,-0.4308234,-4.703178,99.99086,0.02573368,-0.0025718
38.096,408.5556,4.842134,-7.536957,-0.43251,-4.724031,99.99186,0.02688192,-0.0025631
38.196,409.5539,4.839597,-7.562928,-0.4342646,-4.745646,99.96091,0.02829681,-0.0025499
38.296,410.5497,4.83667,-7.587314,-0.4359128,-4.766113,100.0046,0.02987834,-0.002525
38.396,411.5508,4.833672,-7.612084,-0.437575,-4.786756,99.97451,0.03129482,-0.0024821
38.496,412.55,4.830644,-7.636864,-0.439233,-4.807376,100.0376,0.03268912,-0.0023869
38.596,413.5463,4.8274,-7.662875,-0.4409594,-4.828756,100.0063,0.03435848,-0.0022184
38.696,414.5416,4.823752,-7.684991,-0.4424348,-4.847406,99.9983,0.03623545,-0.0019144
38.796,415.5468,4.82023,-7.7068,-0.4438824,-4.865782,100.0177,0.03812441,-0.0014227
38.896,416.5406,4.816601,-7.726264,-0.4451807,-4.882528,100.0268,0.0398959,-0.00090435
38.996,417.5395,4.812588,-7.736168,-0.4458744,-4.892648,100.0178,0.04167418,-0.00044703
39.096,418.5388,4.80809,-7.739031,-0.4461324,-4.897951,100.0069,0.04378902,-0.00012519
39.196,419.5413,4.803517,-7.721905,-0.4451497,-4.88961,100.002,0.04607697,3.38069e-05
39.296,420.541,4.7989,-7.693225,-0.4434569,-4.873459,100.005,0.04840646,5.86855e-05
39.396,421.543,4.794922,-7.695159,-0.4436512,-4.878032,100.0202,0.05114126,-6.338e-05
39.496,422.5406,4.789326,-7.704626,-0.4443094,-4.887716,99.99397,0.05425637,-0.00033518
39.596,423.539,4.78363,-7.71792,-0.4451934,-4.899882,99.98231,0.05732618,-0.00068717
39.696,424.5334,4.778344,-7.72975,-0.4459832,-4.911018,99.99984,0.06045437,-0.001034
39.796,425.5322,4.772682,-7.739701,-0.4466493,-4.920802,99.99842,0.0639709,-0.001289
39.896,426.5403,4.764936,-7.75278,-0.4474986,-4.932626,100.0278,0.0674522,-0.0014096
39.996,427.539,4.758156,-7.767158,-0.4484239,-4.945291,100.0217,0.07064312,-0.00151
40.096,428.54,4.751539,-7.781339,-0.4493298,-4.957758,99.98624,0.07415313,-0.0016288
40.196,429.5417,4.74417,-7.7981,-0.4503852,-4.971884,100.0287,0.07784455,-0.0017639
40.296,430.5439,4.736124,-7.818965,-0.4516808,-4.988672,100.0295,0.08134976,-0.0018896
40.396,431.5408,4.728165,-7.836126,-0.4527448,-5.002911,100.0295,0.08499431,-0.0020013
40.496,432.5426,4.719717,-7.857059,-0.4540258,-5.019561,99.97359,0.08936356,-0.0021118
40.596,433.5406,4.710836,-7.878603,-0.455337,-5.036559,100.0117,0.09392826,-0.0022152
40.696,434.5404,4.701218,-7.90085,-0.4566809,-5.053935,100.0403,0.09820472,-0.0023055
40.796,435.5394,4.691467,-7.923919,-0.4580639,-5.071756,100.0102,0.102827,-0.0024105
40.896,436.5397,4.681036,-7.947308,-0.4594564,-5.0897,99.98982,0.1077563,-0.0025221
40.996,437.5418,4.670196,-7.97374,-0.4610211,-5.109569,100.0081,0.1126808,-0.0026277
41.096,438.5394,4.658821,-7.999145,-0.4625214,-5.128674,99.962,0.1177049,-0.0027437
41.196,439.5376,4.647226,-8.02739,-0.4641814,-5.149524,99.9963,0.1228278,-0.0028668
41.296,440.5371,4.634898,-8.055984,-0.465851,-5.170507,100.0183,0.1278459,-0.0029917
41.396,441.5294,4.62192,-8.085188,-0.467548,-5.1918,100.0047,0.1327779,-0.0031144
41.496,442.5268,4.608717,-8.117066,-0.4693929,-5.214768,100.0002,0.1375985,-0.0032368
41.596,443.521,4.59463,-8.149462,-0.4712543,-5.237922,100.0124,0.1421259,-0.003355
41.696,444.5175,4.580489,-8.184039,-0.473233,-5.262408,100.0121,0.146422,-0.0034751
41.796,445.517,4.566026,-8.217728,-0.475145,-5.286176,100.019,0.1504418,-0.0035981
41.896,446.5123,4.550704,-8.253732,-0.4771839,-5.31138,100.0229,0.1541296,-0.0037164
41.996,447.5128,4.53547,-8.290746,-0.4792644,-5.337061,99.992,0.1576633,-0.0038309
42.096,448.5074,4.519867,-8.328175,-0.4813613,-5.362959,100.0013,0.1609198,-0.0039437
42.196,449.5041,4.503756,-8.3684,-0.483605,-5.3905,100.0131,0.1640123,-0.0040556
42.296,450.5012,4.487426,-8.40835,-0.4858187,-5.417734,99.98999,0.166672,-0.0041615
42.396,451.5019,4.470866,-8.450782,-0.4881626,-5.446454,100.044,0.1688276,-0.0042338
42.496,452.4978,4.453804,-8.494184,-0.4905494,-5.475669,99.98906,0.170695,-0.0042842
42.596,453.4994,4.436926,-8.536126,-0.4928337,-5.503772,99.99995,0.172065,-0.0043077
42.696,454.4896,4.419907,-8.580851,-0.4952683,-5.53356,100.0182,0.1728564,-0.0042906
42.796,455.491,4.402734,-8.623801,-0.4975794,-5.562002,99.98974,0.173369,-0.0042628
42.896,456.4828,4.385834,-8.664137,-0.4997288,-5.588664,100.0202,0.1735334,-0.0042227
42.996,457.4816,4.368566,-8.706728,-0.5019894,-5.61659,99.97364,0.1735964,-0.0041878
43.096,458.4762,4.351498,-8.745962,-0.5040466,-5.64221,100.0035,0.1735346,-0.0041636
43.196,459.4765,4.33467,-8.783832,-0.5060114,-5.6668,100.017,0.1734132,-0.0041609
43.296,460.4736,4.317553,-8.827163,-0.5082766,-5.694766,100.0295,0.1733466,-0.0041848
43.396,461.4698,4.300396,-8.866226,-0.5102828,-5.719861,100.0013,0.1732594,-0.0042168
43.496,462.466,4.28341,-8.908744,-0.5124711,-5.74701,100.0127,0.1729403,-0.0042421
43.596,463.4668,4.266342,-8.951343,-0.5146465,-5.774043,99.98066,0.1725305,-0.0042659
43.696,464.4683,4.249478,-8.99392,-0.5168048,-5.800908,99.99169,0.1716992,-0.004246
43.796,465.4621,4.232234,-9.038031,-0.5190394,-5.828648,100.031,0.1703653,-0.004194
43.896,466.4617,4.215396,-9.07921,-0.5210868,-5.854309,100.0134,0.1686145,-0.004107
43.996,467.4578,4.198948,-9.121239,-0.523168,-5.880359,99.98587,0.1665621,-0.0039943
44.096,468.457,4.182425,-9.159076,-0.5249937,-5.903568,99.97638,0.1641608,-0.0038609
44.196,469.4509,4.166589,-9.196161,-0.5267649,-5.926186,100.0558,0.1615185,-0.0037146
44.296,470.4534,4.15079,-9.231452,-0.5284132,-5.947436,100.0043,0.158543,-0.0035582
44.396,471.453,4.135303,-9.265522,-0.5299802,-5.967793,100.0116,0.1555331,-0.0033987
44.496,472.451,4.12014,-9.298562,-0.531475,-5.987348,100.0458,0.1522102,-0.0032252
44.596,473.4502,4.105185,-9.330992,-0.53292,-6.006356,100.0409,0.1485608,-0.0030601
44.696,474.4478,4.090524,-9.360175,-0.5341684,-6.023164,100.0016,0.1448934,-0.0028896
44.796,475.4474,4.076502,-9.386676,-0.5352508,-6.03811,100.0132,0.1409715,-0.0027404
44.896,476.4406,4.062682,-9.413225,-0.5363262,-6.052984,100.0169,0.1369368,-0.002588
44.996,477.441,4.049663,-9.43641,-0.5371955,-6.065551,100.0145,0.13257,-0.0024543
45.096,478.4426,4.037,-9.458902,-0.5380132,-6.07752,99.98136,0.1281496,-0.0023328
45.196,479.4402,4.024224,-9.480926,-0.5387964,-6.089101,100.0034,0.1236855,-0.0022259
45.296,480.4367,4.012219,-9.503722,-0.5396106,-6.101038,99.99982,0.1192693,-0.0021392
45.396,481.4334,4.00079,-9.523285,-0.5402315,-6.110796,99.99234,0.1148382,-0.002061
45.496,482.4315,3.989809,-9.543853,-0.5408952,-6.121042,100.0131,0.1104591,-0.001978
45.596,483.4322,3.97917,-9.56192,-0.541406,-6.12957,100.0313,0.1061441,-0.0019014
45.696,484.4324,3.96904,-9.579595,-0.5418834,-6.137725,99.96931,0.1018118,-0.0018354
45.796,485.4282,3.959078,-9.598754,-0.5424336,-6.146708,99.96808,0.09753989,-0.001792
45.896,486.425,3.949978,-9.615126,-0.5428168,-6.153794,100.0327,0.09332934,-0.0017709
45.996,487.4244,3.94061,-9.6313,-0.5431754,-6.160616,100.0406,0.0892315,-0.0017698
46.096,488.426,3.932071,-9.646957,-0.5434926,-6.16698,100.0052,0.08514624,-0.001793
46.196,489.4254,3.923899,-9.665262,-0.5439451,-6.174872,99.9959,0.08117694,-0.0018407
46.296,490.4266,3.916361,-9.683178,-0.5443627,-6.182375,100.0293,0.07713616,-0.0019062
46.396,491.4236,3.909134,-9.703332,-0.5448938,-6.19118,100.0114,0.07367856,-0.0019802
46.496,492.427,3.902081,-9.721549,-0.5453016,-6.198582,99.97164,0.06987208,-0.0020653
46.596,493.4274,3.89524,-9.743518,-0.5459042,-6.208204,99.94441,0.06671225,-0.0021491
46.696,494.4264,3.888921,-9.766009,-0.546523,-6.218009,100.0103,0.06379218,-0.0022351
46.796,495.423,3.882825,-9.786957,-0.5470459,-6.226738,100.0025,0.06123922,-0.002324
46.896,496.4254,3.876692,-9.809584,-0.5476433,-6.23632,100.0172,0.05828557,-0.002429
46.996,497.4254,3.871383,-9.834508,-0.5483536,-6.2472,100.0122,0.05568548,-0.0025237
47.096,498.4267,3.86606,-9.858746,-0.5490137,-6.257489,100.0342,0.0531929,-0.0026108
47.196,499.425,3.860847,-9.886522,-0.5498542,-6.269836,100.0587,0.05093374,-0.0027231
47.296,500.4253,3.856003,-9.913716,-0.5506479,-6.281648,99.95702,0.04855156,-0.0028589
47.396,501.4212,3.85127,-9.942551,-0.5515183,-6.294346,100.01,0.0462501,-0.0029838
47.496,502.4226,3.847037,-9.971106,-0.5523559,-6.306676,99.98984,0.04403969,-0.0031078
47.596,503.4186,3.842676,-9.998601,-0.553125,-6.318234,100.0231,0.04185255,-0.0032156
47.696,504.4144,3.838476,-10.03527,-0.5543736,-6.33527,100.0424,0.03977134,-0.0033068
47.796,505.41,3.834732,-10.07057,-0.555534,-6.351307,100.0099,0.03787005,-0.0033954
47.896,506.4038,3.831692,-10.10414,-0.5565872,-6.366135,100.0274,0.03623736,-0.0034567
47.996,507.4054,3.828028,-10.13878,-0.557678,-6.381404,99.98012,0.03462612,-0.0035066
48.096,508.405,3.82457,-10.17338,-0.5587531,-6.396514,99.98595,0.03310416,-0.0035325
48.196,509.4031,3.82158,-10.20751,-0.559789,-6.41119,100.0254,0.03180652,-0.0035422
48.296,510.3985,3.818317,-10.24375,-0.5609252,-6.427014,99.99842,0.03070664,-0.003592
48.396,511.3964,3.815292,-10.27666,-0.5618684,-6.440637,99.95841,0.02956967,-0.0036619
48.496,512.3994,3.812666,-10.31309,-0.562981,-6.45622,100.0178,0.02845632,-0.0037437
48.596,513.4022,3.809987,-10.34913,-0.5640578,-6.471411,99.98837,0.02756674,-0.0038381
48.696,514.4036,3.807385,-10.38799,-0.5652705,-6.488172,99.99988,0.02670027,-0.0039396
48.796,515.3998,3.804681,-10.42991,-0.566635,-6.506674,99.9937,0.02593567,-0.0040403
48.896,516.3993,3.802269,-10.46829,-0.5677957,-6.522855,100.0316,0.0253613,-0.0041346
48.996,517.3997,3.799648,-10.51074,-0.5691553,-6.541334,99.99887,0.02489176,-0.0042233
49.096,518.3984,3.797227,-10.55134,-0.5704082,-6.55856,99.955,0.02437744,-0.0042945
49.196,519.3907,3.794936,-10.59581,-0.5718564,-6.578016,100.0049,0.02359708,-0.0043648
49.296,520.3894,3.792626,-10.6379,-0.5731619,-6.595842,99.99649,0.02302378,-0.0044497
49.396,521.3911,3.790384,-10.68161,-0.574534,-6.614462,100.0117,0.02234444,-0.004544
49.496,522.39,3.788106,-10.72618,-0.5759396,-6.633478,100.0191,0.02174612,-0.0046355
49.596,523.3873,3.786189,-10.77153,-0.577373,-6.652825,100.0198,0.02120726,-0.0047385
49.696,524.3847,3.784095,-10.82022,-0.578966,-6.674024,100.0045,0.02070488,-0.0048338
49.796,525.3795,3.782158,-10.86842,-0.5805214,-6.6948,99.98884,0.02028227,-0.0049394
49.896,526.3813,3.780175,-10.91698,-0.582077,-6.715591,100.0044,0.01986624,-0.0050507
49.996,527.3731,3.778186,-10.96684,-0.583691,-6.73708,99.9743,0.01958055,-0.0051801
50.096,528.3741,3.776382,-11.01781,-0.5853438,-6.759028,100.0189,0.01944119,-0.005352
50.196,529.368,3.7745,-11.06907,-0.5870004,-6.78104,99.98585,0.01932204,-0.0056268
50.296,530.3676,3.772516,-11.12291,-0.5887737,-6.80441,100.0034,0.01920464,-0.0059926
50.396,531.3591,3.77074,-11.17918,-0.590663,-6.829138,100.0247,0.01910474,-0.0063976
50.496,532.3615,3.768876,-11.23895,-0.59271,-6.855714,100.0272,0.01908116,-0.0067939
50.596,533.3606,3.766874,-11.31142,-0.5953937,-6.889694,99.97699,0.01898825,-0.0071404
50.696,534.3582,3.764926,-11.39297,-0.5985289,-6.928916,100.0172,0.0190023,-0.0073937
50.796,535.3587,3.76339,-11.47418,-0.6016269,-6.967735,100.0158,0.01882332,-0.007531
50.896,536.3568,3.76122,-11.55306,-0.6045889,-7.00501,100.0423,0.01863689,-0.0075428
50.996,537.3518,3.759632,-11.62712,-0.6072901,-7.039291,99.99012,0.01843257,-0.0074244
51.096,538.3459,3.757686,-11.69937,-0.609887,-7.072356,100.0327,0.01831071,-0.0071959
51.196,539.3418,3.755847,-11.7666,-0.6122107,-7.10227,99.96164,0.01831377,-0.0069393
51.296,540.3363,3.754266,-11.83172,-0.6144141,-7.13081,99.99494,0.01816011,-0.0067036
51.396,541.3338,3.75241,-11.89719,-0.6166172,-7.159372,99.9741,0.01812896,-0.0064957
51.496,542.3286,3.750412,-11.95933,-0.6186409,-7.185864,100.0381,0.01812389,-0.0063215
51.596,543.3281,3.748925,-12.02042,-0.6205921,-7.211544,100.0005,0.01811067,-0.006199
51.696,544.3282,3.74697,-12.07996,-0.6224498,-7.236165,99.99887,0.01832422,-0.0061137
51.796,545.3254,3.745306,-12.13668,-0.6241559,-7.259032,100.0577,0.01845137,-0.0060619
51.896,546.326,3.743375,-12.19579,-0.6259674,-7.283141,99.99455,0.01843372,-0.0060534
51.996,547.3214,3.741672,-12.25522,-0.6277856,-7.307349,100.0383,0.0185236,-0.0060939
52.096,548.3182,3.73987,-12.31409,-0.6295627,-7.331088,99.98832,0.01881588,-0.0061782
52.196,549.3164,3.737998,-12.37405,-0.6313813,-7.35533,99.98822,0.0190246,-0.0062985
52.296,550.3157,3.735826,-12.43607,-0.633289,-7.380632,100.0099,0.01929659,-0.0064454
52.396,551.314,3.734411,-12.49941,-0.6352502,-7.40658,99.96832,0.01966594,-0.0066038
52.496,552.3105,3.732212,-12.56631,-0.6373781,-7.434486,100.0014,0.02007511,-0.0067613
52.596,553.3098,3.730356,-12.6336,-0.63951,-7.462461,99.98101,0.02055349,-0.0069315
52.696,554.3054,3.728214,-12.70299,-0.6417364,-7.49156,99.99984,0.02114318,-0.007097
52.796,555.3016,3.726106,-12.77421,-0.6440422,-7.521598,99.99355,0.02162018,-0.0072403
52.896,556.2964,3.723992,-12.8456,-0.6463434,-7.551604,99.98514,0.02215228,-0.0073718
52.996,557.2924,3.721812,-12.91936,-0.6487476,-7.582842,100.0188,0.02263162,-0.0074936
53.096,558.288,3.719544,-12.99293,-0.6511313,-7.613832,99.99238,0.02325873,-0.0076054
53.196,559.2855,3.717152,-13.06909,-0.6536331,-7.646184,100.0055,0.02372122,-0.0077032
53.296,560.2837,3.714938,-13.14464,-0.6560886,-7.678028,99.94469,0.0242563,-0.0077932
53.396,561.2832,3.71252,-13.22281,-0.6586589,-7.711241,100.022,0.02480088,-0.0078783
53.496,562.2752,3.710108,-13.30034,-0.6611899,-7.744011,99.99832,0.02534998,-0.007943
53.596,563.2732,3.707291,-13.37944,-0.6637811,-7.777512,100.0425,0.02586973,-0.0080056
53.696,564.2699,3.705002,-13.45778,-0.6663228,-7.810455,99.99364,0.02644791,-0.0080793
53.796,565.2693,3.702278,-13.53933,-0.669004,-7.845068,99.99975,0.0269395,-0.0081379
53.896,566.2616,3.699537,-13.61794,-0.6715369,-7.877947,99.96631,0.02749787,-0.0081942
53.996,567.2572,3.69689,-13.69697,-0.6740736,-7.910905,99.98369,0.02798469,-0.008266
54.096,568.2589,3.694219,-13.7798,-0.6767761,-7.94584,100.016,0.0285607,-0.0083424
54.196,569.257,3.69125,-13.8629,-0.6794819,-7.980839,99.98594,0.02915795,-0.0084282
54.296,570.2542,3.68847,-13.94493,-0.6821226,-8.0151,100.0133,0.02954568,-0.0085003
54.396,571.2562,3.685317,-14.02864,-0.6848255,-8.050129,99.99605,0.03008491,-0.0085641
54.496,572.2508,3.682494,-14.11504,-0.6876543,-8.08665,99.98124,0.03055666,-0.0085957
54.596,573.2495,3.679306,-14.20174,-0.6904819,-8.12318,100.0166,0.03088821,-0.0086049
54.696,574.2437,3.676232,-14.2875,-0.6932549,-8.159089,100.0013,0.03116622,-0.0085895
54.796,575.2406,3.673504,-14.37094,-0.6959003,-8.19353,99.99708,0.03140166,-0.0085252
54.896,576.238,3.669988,-14.45409,-0.6985184,-8.22767,100.0042,0.03172022,-0.0084366
54.996,577.2346,3.666929,-14.53814,-0.7011678,-8.26221,99.99991,0.03198437,-0.0083212
55.096,578.2289,3.664095,-14.61978,-0.703694,-8.295295,99.99824,0.03212174,-0.0082009
55.196,579.2257,3.660642,-14.69874,-0.7060775,-8.32671,99.98516,0.03251958,-0.0080875
55.296,580.2244,3.657631,-14.77696,-0.7084122,-8.357574,99.99969,0.03270396,-0.0079757
55.396,581.2222,3.654046,-14.85554,-0.7107538,-8.38854,99.998,0.03296244,-0.0078762
55.496,582.2232,3.651149,-14.93091,-0.7129278,-8.417553,100.0106,0.03330645,-0.0077845
55.596,583.2204,3.647778,-15.00769,-0.7151622,-8.447293,99.98392,0.03361544,-0.0076275
55.696,584.216,3.644318,-15.08242,-0.7172868,-8.475769,99.98782,0.03369674,-0.0073595
55.796,585.216,3.64116,-15.15798,-0.7194404,-8.504595,99.99508,0.03369064,-0.006992
55.896,586.214,3.637723,-15.23163,-0.7214937,-8.532258,100.0207,0.03356867,-0.0065572
55.996,587.209,3.634302,-15.3028,-0.723677,-8.561478,99.99668,0.03330946,-0.0060628
56.096,588.1974,3.630963,-15.35413,-0.7257047,-8.588861,100.0152,0.03261337,-0.0055293
56.196,589.1981,3.627722,-15.39887,-0.7274759,-8.613244,100.0223,0.03186338,-0.0050219
56.296,590.1966,3.624738,-15.44345,-0.7292389,-8.637539,99.99203,0.03145525,-0.004694
56.396,591.1954,3.621667,-15.48372,-0.7307944,-8.659406,100.0024,0.03094551,-0.0043686
56.496,592.1932,3.618652,-15.52101,-0.7322082,-8.679606,99.99159,0.03036074,-0.0041246
56.596,593.1915,3.61619,-15.55381,-0.7334088,-8.697284,100.0105,0.02976789,-0.0039665
56.68768,594.107,3.613816,-15.58251,-0.7344424,-8.712714,99.97152,0.02903252,-0.0038202